Workbook

Sheet 진행현황
B2: 시장조사 진행현황
B3: 각 잡 시트의 입력값이 자동 반영됩니다. ‘이동’을 누르면 해당 시트로 이동합니다.
K5: 수집 상태
K6: 미착수 | L6: =COUNTIF($H$11:$H$110,K6) -> 36
K7: 수집중 | L7: =COUNTIF($H$11:$H$110,K7) -> 9
K8: 완료 | L8: =COUNTIF($H$11:$H$110,K8) -> 55
B10: Job No. | C10: N잡 이름 | D10: 유형 | E10: 사전정보 | G10: 날짜 | H10: 수집 상태 | I10: 종합 판정 | J10: 실제 종사자 | K10: 인터뷰 가능성 | L10: 이동
B11: 001 | C11: 디지털 마케터 | D11: 1. 디지털·AI 실무형 | E11: AX컨설팅 참여자에게 문의 | F11: 박나경 | H11: =IF('001_디지털 마케터'!C8="","",'001_디지털 마케터'!C8) -> 완료 | I11: =IF('001_디지털 마케터'!C25="","",'001_디지털 마케터'!C25) -> 적합 | J11: =IF('001_디지털 마케터'!C27="","",'001_디지털 마케터'!C27) -> 이재연 세이어바웃 대표, 강남구디지털신중년센터 강사 | K11: =IF('001_디지털 마케터'!C30="","",'001_디지털 마케터'!C30) -> 상 | L11: 이동
B12: 002 | C12: 블로그·SNS 운영대행자 | D12: 1. 디지털·AI 실무형 | F12: 박나경 | G12: 9.9 | H12: =IF('002_블로그·SNS 운영대행자'!C8="","",'002_블로그·SNS 운영대행자'!C8) -> 완료 | I12: =IF('002_블로그·SNS 운영대행자'!C25="","",'002_블로그·SNS 운영대행자'!C25) -> 적합 | J12: =IF('002_블로그·SNS 운영대행자'!C27="","",'002_블로그·SNS 운영대행자'!C27) -> 한결마케팅 / 7년간 기업 마케팅 팀장 근무 / 본인 학원, 독서실 운영 경험 | K12: =IF('002_블로그·SNS 운영대행자'!C30="","",'002_블로그·SNS 운영대행자'!C30) -> 하 | L12: 이동
B13: 003 | C13: 온라인 사무지원 프리랜서 | D13: 1. 디지털·AI 실무형 | E13: 이지태스크에서 연결 | F13: 박나경 | H13: =IF('003_온라인 사무지원 프리랜서'!C8="","",'003_온라인 사무지원 프리랜서'!C8) -> 미착수 | I13: =IF('003_온라인 사무지원 프리랜서'!C25="","",'003_온라인 사무지원 프리랜서'!C25) | J13: =IF('003_온라인 사무지원 프리랜서'!C27="","",'003_온라인 사무지원 프리랜서'!C27) -> 한성아이디 인테리어업체 내 수리홈즈(A/S 전담부서) 중년 여직원 | K13: =IF('003_온라인 사무지원 프리랜서'!C30="","",'003_온라인 사무지원 프리랜서'!C30) -> 중 | L13: 이동 | N13: 한연석 | O13: 010-5386-8006
B14: 004 | C14: 숏폼 영상 편집자 | D14: 1. 디지털·AI 실무형 | F14: 박나경 | H14: =IF('004_숏폼 영상 편집자'!C8="","",'004_숏폼 영상 편집자'!C8) -> 수집중 | I14: =IF('004_숏폼 영상 편집자'!C25="","",'004_숏폼 영상 편집자'!C25) -> 적합 | J14: =IF('004_숏폼 영상 편집자'!C27="","",'004_숏폼 영상 편집자'!C27) | K14: =IF('004_숏폼 영상 편집자'!C30="","",'004_숏폼 영상 편집자'!C30) | L14: 이동
B15: 005 | C15: 데이터 라벨러 | D15: 1. 디지털·AI 실무형 | E15: 데이터라벨러 강사 | F15: 박나경 | G15: 8.28 | H15: =IF('005_데이터 라벨러'!C8="","",'005_데이터 라벨러'!C8) -> 완료 | I15: =IF('005_데이터 라벨러'!C25="","",'005_데이터 라벨러'!C25) -> 적합 | J15: =IF('005_데이터 라벨러'!C27="","",'005_데이터 라벨러'!C27) -> 서유진 / aiworks / 5년 | K15: =IF('005_데이터 라벨러'!C30="","",'005_데이터 라벨러'!C30) -> 상 | L15: 이동
B16: 006 | C16: 앱 사용성 평가원 | D16: 1. 디지털·AI 실무형 | F16: 박나경 | H16: =IF('006_앱 사용성 평가원'!C8="","",'006_앱 사용성 평가원'!C8) -> 미착수 | I16: =IF('006_앱 사용성 평가원'!C25="","",'006_앱 사용성 평가원'!C25) | J16: =IF('006_앱 사용성 평가원'!C27="","",'006_앱 사용성 평가원'!C27) | K16: =IF('006_앱 사용성 평가원'!C30="","",'006_앱 사용성 평가원'!C30) | L16: 이동
B17: 007 | C17: 상세페이지 디자이너 | D17: 1. 디지털·AI 실무형 | F17: 박나경 | H17: =IF('007_상세페이지 디자이너'!C8="","",'007_상세페이지 디자이너'!C8) -> 완료 | I17: =IF('007_상세페이지 디자이너'!C25="","",'007_상세페이지 디자이너'!C25) -> 적합 | J17: =IF('007_상세페이지 디자이너'!C27="","",'007_상세페이지 디자이너'!C27) -> 디자인몽땅 크몽 상위 2% 전문가, 웹에이전시 디자인팀 7년, 프리덴 소파 디자인팀 1.2년, 프리랜서 10년 | K17: =IF('007_상세페이지 디자이너'!C30="","",'007_상세페이지 디자이너'!C30) | L17: 이동
B18: 008 | C18: 유해콘텐츠 모니터링 요원 | D18: 1. 디지털·AI 실무형 | F18: 박나경 | H18: =IF('008_유해콘텐츠 모니터링 요원'!C8="","",'008_유해콘텐츠 모니터링 요원'!C8) -> 미착수 | I18: =IF('008_유해콘텐츠 모니터링 요원'!C25="","",'008_유해콘텐츠 모니터링 요원'!C25) | J18: =IF('008_유해콘텐츠 모니터링 요원'!C27="","",'008_유해콘텐츠 모니터링 요원'!C27) | K18: =IF('008_유해콘텐츠 모니터링 요원'!C30="","",'008_유해콘텐츠 모니터링 요원'!C30) | L18: 이동 | R18: 스타트업엑셀러레이터
B19: 009 | C19: 경영 컨설턴트 | D19: 2. 경영·창업 자문형 | E19: 신철호 추천 -> 정재웅 지인 | F19: 정재웅 | G19: 8.28 | H19: =IF('009_경영 컨설턴트'!C8="","",'009_경영 컨설턴트'!C8) -> 완료 | I19: =IF('009_경영 컨설턴트'!C25="","",'009_경영 컨설턴트'!C25) -> 적합 | J19: =IF('009_경영 컨설턴트'!C27="","",'009_경영 컨설턴트'!C27) -> - 장동철 / 컨설턴트 & 작가 / 현대차, 모비스 인사부문 경력 29년(부사장 은퇴), 현재 경영컨설턴트 (경력 4년) 및 도서 작가 (저서 2권) | K19: =IF('009_경영 컨설턴트'!C30="","",'009_경영 컨설턴트'!C30) -> 중 | L19: 이동 | R19: 평판조회전문가
B20: 010 | C20: 소상공인 컨설턴트 | D20: 2. 경영·창업 자문형 | E20: 신철호 추천 | F20: 정재웅 | G20: 9.11 | H20: =IF('010_소상공인 컨설턴트'!C8="","",'010_소상공인 컨설턴트'!C8) -> 완료 | I20: =IF('010_소상공인 컨설턴트'!C25="","",'010_소상공인 컨설턴트'!C25) -> 적합 | J20: =IF('010_소상공인 컨설턴트'!C27="","",'010_소상공인 컨설턴트'!C27) -> - 윤정혜 대표 / (주)이노밸류 / 소상공인 컨설터트 20년 이상. 경영지도사, 컨설팅학 박사 | K20: =IF('010_소상공인 컨설턴트'!C30="","",'010_소상공인 컨설턴트'!C30) -> 상 | L20: 이동 | R20: ISO품질심사원
B21: 011 | C21: 창업 멘토·컨설턴트 | D21: 2. 경영·창업 자문형 | E21: 상상우리 컨설턴트 추천 -> 김현주 대표 | F21: 정재웅 | G21: 8.28 | H21: =IF('011_창업 멘토·컨설턴트'!C8="","",'011_창업 멘토·컨설턴트'!C8) -> 완료 | I21: =IF('011_창업 멘토·컨설턴트'!C25="","",'011_창업 멘토·컨설턴트'!C25) -> 적합 | J21: =IF('011_창업 멘토·컨설턴트'!C27="","",'011_창업 멘토·컨설턴트'!C27) -> - 김현주 대표 / 공감나무디자인연구소 / 창업컨설턴트 및 커리어 코칭 강사 8년차 | K21: =IF('011_창업 멘토·컨설턴트'!C30="","",'011_창업 멘토·컨설턴트'!C30) -> 상 | L21: 이동 | R21: 생활목공전문가
B22: 012 | C22: 스타트업 액셀러레이터 | D22: 2. 경영·창업 자문형 | E22: MYSC | F22: 정재웅 | G22: 10.14~16 | H22: =IF('012_스타트업 액셀러레이터'!C8="","",'012_스타트업 액셀러레이터'!C8) -> 완료 | I22: =IF('012_스타트업 액셀러레이터'!C25="","",'012_스타트업 액셀러레이터'!C25) -> 적합 | J22: =IF('012_스타트업 액셀러레이터'!C27="","",'012_스타트업 액셀러레이터'!C27) -> - 이한선 전문위원 / MYSC 2.5년 바이오, 헬스캐어 / 제약회사 영업/마케팅 15년, 청년창업사관학교 8년, 서울50+ 입주사 20개사 및 경기도 사회적기업 10개사 담당, 경영지도사 자격증 보유. 60대 초반. - 임성준 파트너 / MYSC 파트너 & 파스타벤처스 대표 / 네이버,카카오 등 12년 이상 근무. 스테이즈 스타트업 창업/운영 10년. MYSC 이사 3년 근무, MYSC 파트너(26.3~ ). 한성대 특임교수, 작가 (AI x 스타트업 등 저서 6권, 브런치 작가). 공인중개사 자격증 보유. | K22: =IF('012_스타트업 액셀러레이터'!C30="","",'012_스타트업 액셀러레이터'!C30) -> 상 | L22: 이동 | N22: 이한선 위원 | O22: 010-6211-2036 | Q22: MYSC근무 | R22: 아파트사전점검
B23: 013 | C23: AI소상공인 컨설턴트 | D23: 2. 경영·창업 자문형 | E23: 상상우리 컨설턴트 -> 이종문 컨설턴트 | F23: 정재웅 | G23: 8.31 | H23: =IF('013_AI소상공인 컨설턴트'!C8="","",'013_AI소상공인 컨설턴트'!C8) -> 완료 | I23: =IF('013_AI소상공인 컨설턴트'!C25="","",'013_AI소상공인 컨설턴트'!C25) -> 적합 | J23: =IF('013_AI소상공인 컨설턴트'!C27="","",'013_AI소상공인 컨설턴트'!C27) -> - 이종문 컨설턴트 / 프리랜서 / 디지털 마케팅 컨설팅 20년, 現 은평구 소속 AI소상공인 컨설팅 2년차 | K23: =IF('013_AI소상공인 컨설턴트'!C30="","",'013_AI소상공인 컨설턴트'!C30) -> 상 | L23: 이동 | R23: 트래블헬퍼
B24: 014 | C24: AI중소기업 컨설턴트 | D24: 2. 경영·창업 자문형 | E24: 상상우리 컨설턴트 -> | F24: 정재웅 | G24: 8.26 | H24: =IF('014_AI중소기업 컨설턴트'!C8="","",'014_AI중소기업 컨설턴트'!C8) -> 완료 | I24: =IF('014_AI중소기업 컨설턴트'!C25="","",'014_AI중소기업 컨설턴트'!C25) -> 적합 | J24: =IF('014_AI중소기업 컨설턴트'!C27="","",'014_AI중소기업 컨설턴트'!C27) -> - 이재우 컨설턴트 / 상상우리 / 전 IT분야 30년 컨설팅 경력, 현 AI중소기업(사회적기업) 컨설턴트 1년차 | K24: =IF('014_AI중소기업 컨설턴트'!C30="","",'014_AI중소기업 컨설턴트'!C30) -> 상 | L24: 이동 | R24: 통학차량동행보호자
B25: 015 | C25: 면접심사위원 | D25: 2. 경영·창업 자문형 | E25: 황성철 추천->앙코르커리어 이소영대표 -> 심영재 | F25: 정재웅 | G25: 9.18 | H25: =IF('015_면접심사위원'!C8="","",'015_면접심사위원'!C8) -> 완료 | I25: =IF('015_면접심사위원'!C25="","",'015_면접심사위원'!C25) -> 적합 | J25: =IF('015_면접심사위원'!C27="","",'015_면접심사위원'!C27) -> - 심영재 면접심사위원(4년) / 한국소비자협회 상무(10년) / 창업멘토(4년), 면접심사위원 강사(2년) / 전 미래에셋증권 지점장(15년) 경력. | K25: =IF('015_면접심사위원'!C30="","",'015_면접심사위원'!C30) -> 상 | L25: 이동
B26: 016 | C26: 평판조회 전문가 | D26: 2. 경영·창업 자문형 | E26: 시니어엔파트너스 | F26: 정재웅 | G26: 10.14~ | H26: =IF('016_평판조회 전문가'!C8="","",'016_평판조회 전문가'!C8) -> 수집중 | I26: =IF('016_평판조회 전문가'!C25="","",'016_평판조회 전문가'!C25) -> 적합 | J26: =IF('016_평판조회 전문가'!C27="","",'016_평판조회 전문가'!C27) -> - 이은정 대표 / 시니어엔파트너스 / 유엔파트너스에서 7년전 분사, --> 평판조회 전문가 추천 예정 | K26: =IF('016_평판조회 전문가'!C30="","",'016_평판조회 전문가'!C30) | L26: 이동 | N26: 이은정 대표-> 추천 예정
B27: 017 | C27: ISO·품질 심사원 | D27: 2. 경영·창업 자문형 | E27: 신철호 추천 | F27: 정재웅 | G27: 10.16 | H27: =IF('017_ISO·품질 심사원'!C8="","",'017_ISO·품질 심사원'!C8) -> 완료 | I27: =IF('017_ISO·품질 심사원'!C25="","",'017_ISO·품질 심사원'!C25) -> 적합 | J27: =IF('017_ISO·품질 심사원'!C27="","",'017_ISO·품질 심사원'!C27) -> - 진성한 대표 / 한국산업기술경영연구원(KIITM) / 한국산업인력공단 산업현장 교수,건국대학교 신산업융합학과 겸임 교수, 다수 기관들의 평가위원/컨설턴트, 작가(공저 저서 2권), 공학박사 및 공장관리기술사, 경영지도사 보유. 전자/통신사 근무 경력 10년 이상. | K27: =IF('017_ISO·품질 심사원'!C30="","",'017_ISO·품질 심사원'!C30) -> 상 | L27: 이동 | N27: 최유나 대표 | O27: 010-5123-4254 | Q27: (주)콘타
B28: 018 | C28: 직업상담사 | D28: 3. 커리어·심리 상담형 | E28: 상상우리 | F28: 박나경 | G28: 8.31 | H28: =IF('018_직업상담사'!C8="","",'018_직업상담사'!C8) -> 완료 | I28: =IF('018_직업상담사'!C25="","",'018_직업상담사'!C25) -> 적합 | J28: =IF('018_직업상담사'!C27="","",'018_직업상담사'!C27) -> 직업상담사 '우연님' / 새일센터 직업상담사 및 가족센터 객원전문상담사(임상심리사, 청소년상담사)로 활동중, 사회복지사 자격 취득 | K28: =IF('018_직업상담사'!C30="","",'018_직업상담사'!C30) -> 중 | L28: 이동
B29: 019 | C29: 중장년 전직지원 컨설턴트 | D29: 3. 커리어·심리 상담형 | E29: 정재웅 추천(국민연금공단 소속) | F29: 박나경 | G29: 9.2 | H29: =IF('019_전직지원 컨설턴트'!C8="","",'019_전직지원 컨설턴트'!C8) -> 완료 | I29: =IF('019_전직지원 컨설턴트'!C25="","",'019_전직지원 컨설턴트'!C25) -> 적합 | J29: =IF('019_전직지원 컨설턴트'!C27="","",'019_전직지원 컨설턴트'!C27) -> 유명열 노후준비 민간 전문강사 / 국민연금공단 중앙노후준비지원센터 | K29: =IF('019_전직지원 컨설턴트'!C30="","",'019_전직지원 컨설턴트'!C30) -> 상 | L29: 이동 | N29: 중장년 추가
B30: 020 | C30: 청년 커리어 코치 | D30: 3. 커리어·심리 상담형 | E30: 박나경 추천 | F30: 박나경 | G30: 9.21 | H30: =IF('020_커리어 코치'!C8="","",'020_커리어 코치'!C8) -> 완료 | I30: =IF('020_커리어 코치'!C25="","",'020_커리어 코치'!C25) -> 적합 | J30: =IF('020_커리어 코치'!C27="","",'020_커리어 코치'!C27) -> 권리안 서울대 소속 컨설턴트 / 시립대 3년, 한국외대 4년 등 총15여년 경력 | K30: =IF('020_커리어 코치'!C30="","",'020_커리어 코치'!C30) -> 중 | L30: 이동 | N30: 청년 추가
B31: 021 | C31: 심리상담사 | D31: 3. 커리어·심리 상담형 | E31: 상담심리사(직업) | F31: 박나경 | G31: 10.2 | H31: =IF('021_심리상담사'!C8="","",'021_심리상담사'!C8) -> 완료 | I31: =IF('021_심리상담사'!C25="","",'021_심리상담사'!C25) -> 부적합 | J31: =IF('021_심리상담사'!C27="","",'021_심리상담사'!C27) | K31: =IF('021_심리상담사'!C30="","",'021_심리상담사'!C30) | L31: 이동
B32: 022 | C32: 타로상담가 | D32: 3. 커리어·심리 상담형 | E32: 신철호 추천 | F32: 박나경 | G32: 10.7 | H32: =IF('022_타로상담가'!C8="","",'022_타로상담가'!C8) -> 완료 | I32: =IF('022_타로상담가'!C25="","",'022_타로상담가'!C25) -> 조건부 | J32: =IF('022_타로상담가'!C27="","",'022_타로상담가'!C27) -> 신봉주 프리랜서, 경력 10년 | K32: =IF('022_타로상담가'!C30="","",'022_타로상담가'!C30) -> 상 | L32: 이동
B33: 023 | C33: 사주명리 상담가 | D33: 3. 커리어·심리 상담형 | F33: 박나경 | G33: 10.7 | H33: =IF('023_사주명리 상담가'!C8="","",'023_사주명리 상담가'!C8) -> 완료 | I33: =IF('023_사주명리 상담가'!C25="","",'023_사주명리 상담가'!C25) -> 조건부 | J33: =IF('023_사주명리 상담가'!C27="","",'023_사주명리 상담가'!C27) -> 재미난 조각가 | K33: =IF('023_사주명리 상담가'!C30="","",'023_사주명리 상담가'!C30) | L33: 이동
B34: 024 | C34: 퍼스널컬러 전문가 | D34: 3. 커리어·심리 상담형 | E34: 박나경 추천 | F34: 박나경 | G34: 8.31 | H34: =IF('024_퍼스널컬러 전문가'!C8="","",'024_퍼스널컬러 전문가'!C8) -> 완료 | I34: =IF('024_퍼스널컬러 전문가'!C25="","",'024_퍼스널컬러 전문가'!C25) -> 적합 | J34: =IF('024_퍼스널컬러 전문가'!C27="","",'024_퍼스널컬러 전문가'!C27) -> 박현정 퍼스널컬러 컨설턴트/ 박디의 컬러랩 대표(패션디자이너 출신) | K34: =IF('024_퍼스널컬러 전문가'!C30="","",'024_퍼스널컬러 전문가'!C30) -> 상 | L34: 이동
B35: 025 | C35: 기업교육 강사 | D35: 4. 교육·강의형 | E35: 정재웅 추천 | F35: 정재웅 | G35: 9.7 | H35: =IF('025_기업교육 강사'!C8="","",'025_기업교육 강사'!C8) -> 완료 | I35: =IF('025_기업교육 강사'!C25="","",'025_기업교육 강사'!C25) -> 적합 | J35: =IF('025_기업교육 강사'!C27="","",'025_기업교육 강사'!C27) -> - 노희성 강사 / 프리랜서 / 전 은행 지역본부장 및 대학 교수 경력 40년, 현 기업 강사/컨설턴트 (세무회계법인 고문), 대학 평가교수, 작가, 숲해설가 3년 - 백영재 대표 / 딥스탠딩파트너스 / 맥킨지컨설팅, CJ그룹, 블리자드코리아, 구글, 필립모리스, 네플릭스 등 25년 경력. 현 기업교육 강사, 연세대 겸임교수, 한투증권 사외이사 | K35: =IF('025_기업교육 강사'!C30="","",'025_기업교육 강사'!C30) -> 상 | L35: 이동
B36: 026 | C36: 디지털·AI 활용 강사 | D36: 4. 교육·강의형 | E36: 권신 강사 | F36: 정재웅 | G36: 9.4 | H36: =IF('026_디지털·AI 활용 강사'!C8="","",'026_디지털·AI 활용 강사'!C8) -> 완료 | I36: =IF('026_디지털·AI 활용 강사'!C25="","",'026_디지털·AI 활용 강사'!C25) -> 적합 | J36: =IF('026_디지털·AI 활용 강사'!C27="","",'026_디지털·AI 활용 강사'!C27) -> - 권신 강사 / 프리랜서 / 상상우리 파트너 강사, 서울시50+재단 강의 7년, 은평구 평생학습관 진로지도사 7년. "오늘도 괜찮아" 등 저서 8권(전자책 3권) | K36: =IF('026_디지털·AI 활용 강사'!C30="","",'026_디지털·AI 활용 강사'!C30) -> 상 | L36: 이동
B37: 027 | C37: 스마트경로당 강사 | D37: 4. 교육·강의형 | E37: 신철호 추천 | F37: 정재웅 | G37: 10.21 | H37: =IF('027_스마트경로당 강사'!C8="","",'027_스마트경로당 강사'!C8) -> 완료 | I37: =IF('027_스마트경로당 강사'!C25="","",'027_스마트경로당 강사'!C25) -> 적합 | J37: =IF('027_스마트경로당 강사'!C27="","",'027_스마트경로당 강사'!C27) -> - 최윤리 강사 / 나누자연협회, 상상우리 / 교육회사(진로, 주도학습, 독서) 강사양성 20년, 시니어/중장년 디지털AI활용(상상우리,2회/4주) 강사 3년. 저서 출판("글쓰기로 오십을 바꾸다" 등 단독 2권, 공저 1권), 시니어디지털지도사 자격증 보유. | K37: =IF('027_스마트경로당 강사'!C30="","",'027_스마트경로당 강사'!C30) -> 상 | L37: 이동 | N37: 최윤리 강사 | O37: 010-9070-0811 | Q37: 스마트경로당 강사도 했으나 근래 디지털/AI 강사에 치중.
B38: 028 | C38: 시니어 대상 강사 | D38: 4. 교육·강의형 | E38: 정재웅 추천 | F38: 정재웅 | G38: 9.21 | H38: =IF('028_시니어 대상 강사'!C8="","",'028_시니어 대상 강사'!C8) -> 완료 | I38: =IF('028_시니어 대상 강사'!C25="","",'028_시니어 대상 강사'!C25) -> 적합 | J38: =IF('028_시니어 대상 강사'!C27="","",'028_시니어 대상 강사'!C27) -> - 이갑숙 교수/박사(노인복지학) / 총신대학교 평생교육원 / 시니어 인지캐어 교수 및 강사 20년 이상, "실버레(뇌)크리에이션"외 2권의 저서 저술. | K38: =IF('028_시니어 대상 강사'!C30="","",'028_시니어 대상 강사'!C30) -> 상 | L38: 이동
B39: 029 | C39: 아동 대상 강사 | D39: 4. 교육·강의형 | E39: 황성철 추천->앙코르커리어 이소영대표 ->(자립청년 금융멘토)복혜정 | F39: 정재웅 | G39: 9.23 | H39: =IF('029_아동 대상 강사'!C8="","",'029_아동 대상 강사'!C8) -> 완료 | I39: =IF('029_아동 대상 강사'!C25="","",'029_아동 대상 강사'!C25) -> 적합 | J39: =IF('029_아동 대상 강사'!C27="","",'029_아동 대상 강사'!C27) -> - 복혜정 강사 / 복드림코칭센터 대표/ 전 외국계 은행 임원 출신, 현 LCMC 부대표, 미국 Gallup 강점인증코치, 재무설계 코치 등 | K39: =IF('029_아동 대상 강사'!C30="","",'029_아동 대상 강사'!C30) -> 상 | L39: 이동 | N39: 이상은 강사 010-3218-8640
B40: 030 | C40: 한국어 교원(외국인 대상) | D40: 4. 교육·강의형 | E40: 온라인, 오프라인 별도 | F40: 정재웅 | G40: 9.28 | H40: =IF('030_한국어 교원(외국인 대상)'!C8="","",'030_한국어 교원(외국인 대상)'!C8) -> 완료 | I40: =IF('030_한국어 교원(외국인 대상)'!C25="","",'030_한국어 교원(외국인 대상)'!C25) -> 적합 | J40: =IF('030_한국어 교원(외국인 대상)'!C27="","",'030_한국어 교원(외국인 대상)'!C27) -> - 김선숙 선생 / 키움터(오후), 경기도이음학교(오전) / 사회복지사, 요양보호사 자격증 보유. 한국어교원 경력 4년 (한국어교원 2급 보유). 항공사 근무 20년.(50대 중반) | K40: =IF('030_한국어 교원(외국인 대상)'!C30="","",'030_한국어 교원(외국인 대상)'!C30) -> 중 | L40: 이동
B41: 031 | C41: 디지털 안내사 | D41: 4. 교육·강의형 | E41: 상상우리 직원(디동플) | F41: 정재웅 | G41: 10.2 | H41: =IF('031_디지털 안내사'!C8="","",'031_디지털 안내사'!C8) -> 완료 | I41: =IF('031_디지털 안내사'!C25="","",'031_디지털 안내사'!C25) -> 적합 | J41: =IF('031_디지털 안내사'!C27="","",'031_디지털 안내사'!C27) -> - 신민화 강사 / 프리랜서 / 영양사로 근무하다가 컴퓨터 강사로 전환. 컴퓨터 강사 10년, 디지털안내사 10년. 현재 50대. | K41: =IF('031_디지털 안내사'!C30="","",'031_디지털 안내사'!C30) -> 중 | L41: 이동 | N41: 최윤리 강사 | O41: 010-9070-0811
B42: 032 | C42: 진로(코칭) 지도사 | D42: 4. 교육·강의형 | E42: 정재웅 지인 추천 | F42: 정재웅 | G42: 9.4 | H42: =IF('032_진로체험 강사'!C8="","",'032_진로체험 강사'!C8) -> 완료 | I42: =IF('032_진로체험 강사'!C25="","",'032_진로체험 강사'!C25) -> 적합 | J42: =IF('032_진로체험 강사'!C27="","",'032_진로체험 강사'!C27) -> - 유재천 대표 / 의미공학연구소 / 포스코 연구원 6년, MBA후 진로지도사 13년 경력, 연세대 미래갬퍼스 겸임교수 | K42: =IF('032_진로체험 강사'!C30="","",'032_진로체험 강사'!C30) -> 상 | L42: 이동
B43: 033 | C43: 시니어 방문학습 지도사 | D43: 4. 교육·강의형 | E43: 인지케어 | F43: 정재웅 | G43: 10.19~21 | H43: =IF('033_시니어 방문학습 지도사'!C8="","",'033_시니어 방문학습 지도사'!C8) -> 완료 | I43: =IF('033_시니어 방문학습 지도사'!C25="","",'033_시니어 방문학습 지도사'!C25) -> 적합 | J43: =IF('033_시니어 방문학습 지도사'!C27="","",'033_시니어 방문학습 지도사'!C27) -> - 유회란 대표 / 나누자연협회 / 은행원, 무역회사, 유치원교사, 직업상담사/취업지원관 등 경력 20년. 사회복지사, 청년지도사, 노인스포츠지도사, 시니어레크리에이션 강사 자격증 보유. 외향형들의 사회생활(전자책) 출판 (작가) | K43: =IF('033_시니어 방문학습 지도사'!C30="","",'033_시니어 방문학습 지도사'!C30) -> 상 | L43: 이동 | N43: 유회란 대표 | O43: 010-3482-3484
...

Sheet 백잡100
A1: Job No. | B1: 유형 | C1: N잡 이름 | D1: N잡 개념 | E1: 초기비용 | F1: 진입난이도 | G1: 시간투여도 | H1: 체력부담 | I1: 유연성 | J1: 근무장소 | K1: 자격요건 | L1: 수익구조
A2: 001 | B2: 1. 디지털·AI 실무형 | C2: 디지털 마케터 | D2: 기업·소상공인의 온라인 광고와 홍보를 대신 기획·집행해 매출로 연결하는 일 | E2: ₩ | F2: ★★★★ | G2: 주15~30h | H2: 하 | I2: 협의가능 | J2: 재택 | K2: 불필요 | L2: 월정액
A3: 002 | B3: 1. 디지털·AI 실무형 | C3: 블로그·SNS 운영대행자 | D3: 업체를 대신해 블로그·인스타그램 등 채널에 콘텐츠를 올리고 계정을 관리하는 일 | E3: ₩ | F3: ★★ | G3: 주5~15h | H3: 하 | I3: 완전자유 | J3: 재택 | K3: 불필요 | L3: 월정액
A4: 003 | B4: 1. 디지털·AI 실무형 | C4: 온라인 사무지원 프리랜서 | D4: 문서 작성, 자료 정리, 일정 관리 등 사무 업무를 원격으로 대행하는 일 | E4: ₩ | F4: ★★ | G4: 주5~15h | H4: 하 | I4: 협의가능 | J4: 재택 | K4: 불필요 | L4: 건별
A5: 004 | B5: 1. 디지털·AI 실무형 | C5: 숏폼 영상 편집자 | D5: 릴스·쇼츠 등 짧은 세로형 영상을 자막·컷 편집해 완성하는 일 | E5: ₩₩ | F5: ★★★ | G5: 주5~15h | H5: 하 | I5: 완전자유 | J5: 재택 | K5: 불필요 | L5: 건별
A6: 005 | B6: 1. 디지털·AI 실무형 | C6: 데이터 라벨러 | D6: AI 학습에 쓰이는 이미지·음성·문장에 정답 표시를 달아주는 일 | E6: ₩ | F6: ★ | G6: 주5~15h | H6: 하 | I6: 완전자유 | J6: 재택 | K6: 불필요 | L6: 건별
A7: 006 | B7: 1. 디지털·AI 실무형 | C7: 앱 사용성 평가원 | D7: 출시 전 앱·웹을 직접 써보고 불편한 점을 찾아 보고하는 일 | E7: ₩ | F7: ★ | G7: 주5h 미만 | H7: 하 | I7: 완전자유 | J7: 재택 | K7: 불필요 | L7: 건별
A8: 007 | B8: 1. 디지털·AI 실무형 | C8: 상세페이지 디자이너 | D8: 온라인 쇼핑몰 상품 소개 페이지를 기획하고 이미지로 제작하는 일 | E8: ₩₩ | F8: ★★★ | G8: 주5~15h | H8: 하 | I8: 완전자유 | J8: 재택 | K8: 불필요 | L8: 건별
A9: 008 | B9: 1. 디지털·AI 실무형 | C9: 유해콘텐츠 모니터링 요원 | D9: 플랫폼에 올라온 게시물·리뷰를 검토해 규정 위반 콘텐츠를 걸러내는 일 | E9: ₩ | F9: ★ | G9: 주15~30h | H9: 하 | I9: 고정 | J9: 재택 | K9: 불필요 | L9: 시간제
A10: 009 | B10: 2. 경영·창업 자문형 | C10: 경영 컨설턴트 | D10: 기업의 경영 문제를 진단하고 개선 방안을 제시하는 일 | E10: ₩ | F10: ★★★★★ | G10: 주5~15h | H10: 하 | I10: 협의가능 | J10: 현장 | K10: 불필요 | L10: 건별
A11: 010 | B11: 2. 경영·창업 자문형 | C11: 소상공인 컨설턴트 | D11: 동네 가게와 소상공인의 매출·운영 문제를 현장에서 진단하고 해결을 돕는 일 | E11: ₩ | F11: ★★★★ | G11: 주5~15h | H11: 중 | I11: 협의가능 | J11: 방문 | K11: 민간자격 | L11: 건별
A12: 011 | B12: 2. 경영·창업 자문형 | C12: 창업 멘토·컨설턴트 | D12: 창업 준비자에게 아이템 검증부터 사업계획·자금까지 조언하는 일 | E12: ₩ | F12: ★★★★ | G12: 주5~15h | H12: 하 | I12: 협의가능 | J12: 현장 | K12: 불필요 | L12: 건별
... A101: 100 | B101: 10. 판매·공간·무인 운영형 | C101: 농어촌민박 운영자 | D101: 농어촌 지역의 주택을 민박으로 등록해 숙박을 제공하는 일 | E101: ₩₩₩₩ | F101: ★★★ | G101: 주15~30h | H101: 중 | I101: 협의가능 | J101: 점포 | K101: 교육이수 | L101: 자산형

Sheet 미채택후보
A1: No. | B1: 유형 | C1: N잡 이름 | D1: N잡 개념
A2: R01 | B2: 1. 디지털·AI 실무형 | C2: PPT·발표자료 디자이너 | D2: 보고서·제안서를 보기 좋은 슬라이드로 만들어주는 일
A3: R02 | B3: 1. 디지털·AI 실무형 | C3: 시장조사·리서치 대행 | D3: 설문 설계와 경쟁사 조사로 필요한 자료를 수집·정리해주는 일
A4: R03 | B4: 1. 디지털·AI 실무형 | C4: 재택 고객센터 상담사 | D4: 집에서 전화·채팅으로 고객 문의에 응대하는 일
A5: R04 | B5: 2. 경영·창업 자문형 | C5: 중대재해·안전보건 컨설턴트 | D5: 기업의 안전보건 체계를 진단하고 중대재해 예방을 자문하는 일
A6: R05 | B6: 2. 경영·창업 자문형 | C6: 행정사 | D6: 인허가와 각종 민원 서류의 작성·제출을 대행하는 일
A7: R06 | B7: 2. 경영·창업 자문형 | C7: 공인중개사 | D7: 부동산 매매와 임대차 거래를 중개하는 일
A8: R07 | B8: 2. 경영·창업 자문형 | C8: 주택관리사(아파트 관리소장) | D8: 아파트 관리사무소를 총괄 운영하는 일
A9: R08 | B9: 2. 경영·창업 자문형 | C9: 재무설계·은퇴설계 상담사 | D9: 자산과 노후 자금 계획을 설계해주는 일
A10: R09 | B10: 2. 경영·창업 자문형 | C10: 세무·회계 기장 보조 | D10: 장부 정리와 전표 입력 등 세무·회계 실무를 보조하는 일
A11: R10 | B11: 2. 경영·창업 자문형 | C11: 경비지도사 | D11: 경비원의 교육과 현장 지도를 담당하는 일
A12: R11 | B12: 2. 경영·창업 자문형 | C12: 법원·기관 조정위원 | D12: 분쟁 당사자 사이에 서서 합의를 이끄는 일
... A43: R42 | B43: 10. 판매·공간·무인 운영형 | C43: 로컬 공동구매 운영자 | D43: 동네 커뮤니티에서 공동구매를 기획·중개해 수수료를 얻는 일
C45: 헤드헌터
C46: 파크골프
C47: 시민기자
C48: 실버인지미술전문가
C49: 그림책심리지도사
C50: 협업퍼실리테이터
C51: 장난감 의사
C52: FDE
C53: AI미디어작가
C54: 청년일자리멘토
C55: 나무의사
C56: 특수학급 돌봄매니저

Sheet 지표집계
B2: 지표별 분포 (100잡)
B4: 초기비용
B5: ₩ | C5: ₩₩ | D5: ₩₩₩ | E5: ₩₩₩₩ | F5: ₩₩₩₩₩
B6: 55 | C6: 31 | D6: 10 | E6: 3 | F6: 1
B8: 진입난이도
B9: ★ | C9: ★★ | D9: ★★★ | E9: ★★★★ | F9: ★★★★★
B10: 14 | C10: 27 | D10: 41 | E10: 15 | F10: 3
B12: 시간투여도
B13: 주5h 미만 | C13: 주5~15h | D13: 주15~30h | E13: 주30h 이상
B14: 8 | C14: 49 | D14: 37 | E14: 6
B16: 체력부담
B17: 하 | C17: 중 | D17: 상
B18: 37 | C18: 41 | D18: 22
B20: 유연성
B21: 완전자유 | C21: 협의가능 | D21: 고정
B22: 41 | C22: 49 | D22: 10
B24: 근무장소
B25: 재택 | C25: 온라인 | D25: 방문 | E25: 현장 | F25: 점포
B26: 17 | C26: 3 | D26: 18 | E26: 55 | F26: 7
B28: 자격요건
B29: 불필요 | C29: 교육이수 | D29: 민간자격 | E29: 국가자격
B30: 45 | C30: 22 | D30: 20 | E30: 13
B32: 수익구조
B33: 건별 | C33: 시간제 | D33: 월정액 | E33: 자산형
B34: 66 | C34: 17 | D34: 6 | E34: 11

Sheet 사용법
B2: N잡스쿨 — 잡별 시장조사 시트
B3: Job No.001~100 · 잡 1개당 시트 1장 · 8개 항목군
B5: 조사 목적 | C5: 워크위즈 LMS 강좌 상세페이지 제작과 개설 우선순위 판단을 위한 시장조사입니다. 도서 원고용 서술 자료는 이 시트에서 다루지 않습니다.
B6: 시트 구성 | C6: ‘사용법’ · ‘진행현황’(100개 자동 집계·바로가기) · ‘★기입예시’ · 001~100 잡별 시트
B7: 입력 위치 | C7: 연노랑 칸에만 입력합니다. ⑧ 참고 URL의 L열은 확인일입니다.
B8: 드롭다운 | C8: 핵심 지표와 10조건 판정은 목록에서 선택합니다. 표기가 흔들리면 100개 비교와 필터가 불가능해집니다.
B9: ② 핵심 지표 | C9: 6개를 한 행에 넣었습니다. 오른쪽 ‘지표 근거·비고’에 숫자의 출처와 기준을 남겨주세요.
B10: ④ 수요 근거 | C10: 교육 수요가 아니라 그 일자리 자체의 수요입니다. 이 일을 시키는 곳이 실제로 있는지, 늘고 있는지를 봅니다.
B11: ⑥ 적합성 검증 | C11: 10조건을 ○△✕로 판정하고, 아래 칸에 △·✕만 사유를 답니다. ○는 설명하지 않아도 됩니다.
B12: ⑦ 실제 종사자 | C12: 이 일로 실제 돈을 버는 사람 1명을 찾습니다. 한 명도 못 찾으면 그 자체가 ⑧ 충분한 수요 조건의 실패 신호입니다.
B13: 주 소스 | C13: 워크넷·한국직업사전 / 크몽·숨고·탈잉·당근알바 / 자격 발급기관 / 통계청·업종 협회 / 관련 기사·유튜브·블로그
B14: 기준 시점 | C14: 모든 수치는 2026년 기준으로 통일하고, 확인일을 반드시 남깁니다.

Sheet ★기입예시
A1: ;ㅣㅏㅓㅕㅅㄱㄴ ㅠㅠㅜ3ㅕㅑ\
B2: Job No. 001 디지털 마케터
B3: 1. 디지털·AI 실무형 | 워크위즈 N잡스쿨 · 잡별 시장조사 시트 | ※ 기입 예시 (실제 조사값 아님)
B5: ① 기본 정보
B6: 직업명 · 별칭 | C6: 디지털 마케터 / 온라인 마케터 · 퍼포먼스 마케터 · SNS 마케팅 대행
B7: 한 줄 소개 (30자 내외) | C7: 소상공인의 온라인 광고와 채널을 대신 운영해 매출을 만드는 일
B8: 수집 상태 · 담당자 | C8: 완료 | E8: 담당: 홍길동
B9: ② 핵심 지표 6종
B10: 지표 | C10: 초기비용 | D10: 월수익(만원) | E10: 성장성 | F10: 진입난이도 | G10: 주간 소요시간 | H10: 체력부담 | I10: 지표 근거 · 비고
B11: 값 | C11: ₩ 50만 미만 | D11: 80~300 | E11: ↗ 보통 | F11: ★★★ | G11: 주 5~15시간 | H11: 하 | I11: 월수익은 거래처 2~4곳 기준 (크몽 대행 견적 구간, 2026.08 확인)
B12: ③ 하는 일
B13: 하는 일 (3줄 요약) | C13: 소상공인·중소기업의 네이버·인스타그램 채널을 대신 운영한다. 광고 예산을 집행하고 콘텐츠를 발행하며 주 단위로 성과를 보고한다. 보통 업체 2~4곳을 월정액으로 맡아 재택으로 처리한다.
B14: ④ 일자리 수요 근거
B15: 수요처 유형 · 규모 · 증감 추세 | C15: 수요처는 온라인 판매를 시작하려는 소상공인과 지역 중소기업이다. 소상공인 디지털전환 지원사업으로 정부 예산이 붙은 컨설팅·대행 수요가 늘고 있고, 크몽·숨고의 마케팅 대행 카테고리 거래도 꾸준히 유지되고 있다.
B16: 뒷받침 근거 | C16: 복합 | E16: 정부 소상공인 디지털전환 사업 + 재능거래 플랫폼 거래량
B17: ⑤ 진입 방법
B18: 필요 자격 · 교육 | C18: 필수 자격 없음. 네이버 광고·메타 광고 실습 교육 2~3개월이면 진입 가능
B19: 초기 준비물 · 비용 | C19: 노트북, 광고 계정, 포트폴리오용 샘플 리포트. 실비 50만원 미만
B20: 일감 얻는 경로 (플랫폼·기관 실명) | C20: 크몽·숨고 전문가 등록, 소상공인시장진흥공단 컨설턴트 풀, 지자체 소상공인 지원센터, 기존 거래처 소개
B21: ⑥ N잡 적합성 검증
B22: 10조건 | C22: ①시간 유연성 | D22: ②체력 감당 | E22: ③직업 이미지 | F22: ④재미 | G22: ⑤전문성 축적 | H22: ⑥일한 만큼 이상 수익 | I22: ⑦우상향 수익 | J22: ⑧충분한 수요 | K22: ⑨진입 가능성 | L22: ⑩직업적 자부심
B23: 판정 ○ △ ✕ | C23: ○ | D23: ○ | E23: ○ | F23: △ | G23: ○ | H23: ○ | I23: ○ | J23: ○ | K23: △ | L23: ○
B24: 판정 근거 (△·✕ 위주로) | C24: ④ △ — 성과 압박이 있어 숫자에 스트레스를 받는 성향이면 오래 못 간다. ⑨ △ — 자격은 없지만 광고 툴 실습 2~3개월이 필요해 '바로 시작'은 어렵다.
B25: 종합 판정 | C25: 적합 | E25: 10조건 중 8개 통과, 2개 조건부
B26: ⑦ 실제 종사자 (1명)
B27: 이름 · 소속 · 경력 | C27: ○○○ / 프리랜서 / 전 유통기업 영업팀 20년, 現 소상공인 마케팅 대행 4년차
B28: 확인 출처 (기사·인터뷰·블로그·유튜브·플랫폼 프로필 등) | C28: 소상공인시장진흥공단 우수 컨설턴트 인터뷰 기사 (2025) / 본인 네이버 블로그 운영
B29: 컨택 포인트 (연락처·이메일·SNS·소속 기관) | C29: 블로그 댓글·이메일 공개, 공단 컨설턴트 풀 통해 연결 가능
B30: 인터뷰 가능성 | C30: 상 | E30: 강사 후보로도 적합 — 실무 시연 영상화 가능
B31: ⑧ 참고 URL (오른쪽 끝 칸 = 확인일)
B32: URL ①
B33: URL ②
B34: URL ③
B35: URL ④
B36: URL ⑤
B38: ※ 연노랑 칸에 입력합니다. L열은 확인일입니다.

Sheet 001_디지털 마케터
B2: Job No. 001 디지털 마케터
B3: 1. 디지털·AI 실무형 | 워크위즈 N잡스쿨 · 잡별 시장조사 시트
B5: ① 기본 정보
B6: 직업명 · 별칭 | C6: 디지털 마케터
B7: 한 줄 소개 (30자 내외) | C7: 기업의 온라인 홍보를 총괄
B8: 수집 상태 · 담당자 | C8: 완료 | E8: 박나경
B9: ② 핵심 지표 6종
B10: 지표 | C10: 초기비용 | D10: 월수익(만원) | E10: 성장성 | F10: 진입난이도 | G10: 주간 소요시간 | H10: 체력부담 | I10: 지표 근거 · 비고
B11: 값 | C11: ₩ 50만 미만 | D11: 100만원~230만원 | E11: ↗ 보통 | F11: ★★★ | G11: 주 5~15시간 | H11: 하 | I11: 초기 진입 : 소상공인 디지털 마케팅 한달 비용 30만원 3곳 계약시 월 90만원
B12: ③ 하는 일
B13: 하는 일 (3줄 요약) | C13: SNS 콘텐츠 마케팅 : 카드뉴스, 숏폼 영상 제작 및 게시 일정 관리. 댓글과 고객 반응 분석, 콘텐츠 개선 상품 상세페이지 기획 : 상세페이지 구성, 광고문구, 구도 유도 콘텐츠 작성 / 구매전환을 높이는 페이지 제작 온라인 광고 운영 : 네이버 검색광고, 메타 광고 등 설정/ 광고예산 관리 및 타깃 설정/ 클릭률, 구매전환율, 광고수익률 분석 블로그 검색, 노출 마케팅 : 검색에 유용한 블로그 글과 웹사이트 콘텐츠 제작, 검색유입과 문의 수를 분석하고 개선 마케팅 전략 개선 : 고객 유입 경로와 구매 과정을 분석해 매출 개선 전략과 성과 보고서 작성
B14: ④ 일자리 수요 근거
B15: 수요처 유형 · 규모 · 증감 추세 | C15: 광고 대행사나 마케팅 전문회사, 온라인쇼핑몰 브랜드 사업자, 소상공인 등에서 꾸준한 수요 발생. 나스미디어의 2026년 자료에 따르면 2026년 국내 디지털 광고시장은 약 11조 4945억원 규모로 전년대비 약 7.2% 성장 전망
B16: 뒷받침 근거 | C16: 플랫폼 거래량 | E16: 『2025~2035 정성적 일자리 전망』 발간 | 고용노동부 > 뉴스·소식 > 보도·설명 > 보도자료
B17: ⑤ 진입 방법
B18: 필요 자격 · 교육 | C18: 채용시장에서 검색광고마케터 1급, Google Analystics 관련 역량, 광고 운영 경험 등을 우대 조건으로 제시
B19: 초기 준비물 · 비용 | C19: 디자인, 콘텐츠 제작 도구(월 10만원), 검색광고마케터 실무교육(한국자격증협회 등 발급비용 8~10만원)
B20: 일감 얻는 경로 (플랫폼·기관 실명) | C20: 크몽에 등록하여 활동/ 숨고에 마케팅 서비스 제공자로 고객 문의 확보/ 사람인, 잡코리아에서 디지털 마케터 공고 검색
B21: ⑥ N잡 적합성 검증
B22: 10조건 | C22: ①시간 유연성 | D22: ②체력 감당 | E22: ③직업 이미지 | F22: ④재미 | G22: ⑤전문성 축적 | H22: ⑥일한 만큼 이상 수익 | I22: ⑦우상향 수익 | J22: ⑧충분한 수요 | K22: ⑨진입 가능성 | L22: ⑩직업적 자부심
B23: 판정 ○ △ ✕ | C23: ○ | D23: ○ | E23: ○ | F23: ○ | G23: ○ | H23: ○ | I23: △ | J23: ○ | K23: △ | L23: ○
B24: 판정 근거 (△·✕ 위주로) | C24: 중장년이 프리랜서 디지털마케터로 활동하려면 타깃을 소상공인으로 잡는게 현실적이라 우상향 수익이 발생한다고 보기는 어렵고, 상세페이지 디자인이나 숏폼영상 편집 등 단순작업에 비해 기획력과 분석력이 요구되는 분야라 진입 허들이 있음
B25: 종합 판정 | C25: 적합 | E25: x가 없어 적합 판정
B26: ⑦ 실제 종사자 (1명)
B27: 이름 · 소속 · 경력 | C27: 이재연 세이어바웃 대표, 강남구디지털신중년센터 강사
B28: 확인 출처 (기사·인터뷰·블로그·유튜브·플랫폼 프로필 등) | C28: https://search.naver.com/search.naver?where=nexearch&sm=tab_etc&mra=bjky&x_csa=%7B%22fromUi%22%3A%22kb%22%7D&pkid=1&os=29721545&qvt=0&query=%EC%9D%B4%EC%9E%AC%EC%97%B0%20%EC%84%B8%EC%9D%B4%EC%96%B4%EB%B0%94%EC%9B%83
B29: 컨택 포인트 (연락처·이메일·SNS·소속 기관) | C29: 010-2585-3488
B30: 인터뷰 가능성 | C30: 상 | E30: 언제든지 전화하라고 하심
B31: ⑧ 참고 URL (오른쪽 끝 칸 = 확인일)
B32: URL ① | C32: https://blog.naver.com/iybcz670/224384575907
B33: URL ② | C33: https://blog.naver.com/newjin14/224395865778
B34: URL ③ | C34: https://kmong.com/gig/794765#gig-rate-evaluation 단건은 4~10만원
B35: URL ④ | C35: https://www.albamon.com/jobs/detail/119874931 | L35: 주급 39만원
B36: URL ⑤ | C36: https://www.albamon.com/jobs/detail/502061691 | L36: 연봉2700
B38: ※ 연노랑 칸에 입력합니다. L열은 확인일입니다.

Sheet 002_블로그·SNS 운영대행자
B2: Job No. 002 블로그·SNS 운영대행자
B3: 1. 디지털·AI 실무형 | 워크위즈 N잡스쿨 · 잡별 시장조사 시트
B5: ① 기본 정보
B6: 직업명 · 별칭 | C6: 블로그·SNS 운영대행자
B7: 한 줄 소개 (30자 내외) | C7: 다양한 콘텐츠를 제작, 포스팅하며 의뢰업체의 SNS 채널 전반을 전담 운영
B8: 수집 상태 · 담당자 | C8: 완료 | E8: 박나경
B9: ② 핵심 지표 6종
B10: 지표 | C10: 초기비용 | D10: 월수익(만원) | E10: 성장성 | F10: 진입난이도 | G10: 주간 소요시간 | H10: 체력부담 | I10: 지표 근거 · 비고
B11: 값 | C11: ₩ 50만 미만 | D11: 120만원~200만원 | E11: ↗ 보통 | F11: ★★ | G11: 주 15~30시간 | H11: 중 | I11: 시급 12000원 기준 하루 5시간, 주 5일 근무시 월 120만원 ( 보통 시급 12000원~15000원선)
B12: ③ 하는 일
B13: 하는 일 (3줄 요약) | C13: 콘텐츠 제작 : 판매 상품이나 서비스에 대한 영상 및 사진을 기획의도에 맞게 촬영하고 편집하여 다양한 정보성 콘텐츠를 제작 업로드 및 관리 : 다수의 SNS 채널을 관리하며 제품이나 서비스에 관련 글을 주기적으로 올리면서 브랜드 인지도를 관리 댓글 및 Q&A 응대 : 소비자 반응이나 문의가 오면 신속하게 응대하여 예약 또는 계약 등 매출로 연결될 수 있도록 노력
B14: ④ 일자리 수요 근거
B15: 수요처 유형 · 규모 · 증감 추세 | C15: 오프라인 시장보다 사회관계망 중심의 광고 비중이 확대되고 있어 소상공인이나 자영업자들도 직접 하기 어려운 온라인 마케팅을 대신 처리해주는 sns 운영 대행 서비스를 필요로 하고 있어 향후 더욱 수요가 늘 것으로 예상.
B16: 뒷받침 근거 | C16: 플랫폼 거래량 | E16: 크몽 기준 블로그관리 2528개 서비스, 인스타관리 843개 서비스, 유튜브관리 307개 서비스, 릴스쇼츠틱톡관리 195개 서비스 존재
B17: ⑤ 진입 방법
B18: 필요 자격 · 교육 | C18: 국가공인자격증은 없고 SNS마케팅대행전문가 자격증(HBIZ 발급) 등 다양한 민간등록자격증이 존재. 지자체에서도 SNS크리에이터 과정, 영상편집과정 등 해당직업에 도움이 되는 다수의 강의 운영중
B19: 초기 준비물 · 비용 | C19: 민간등록자격증은 대부분 무료강의로 진행되며 수료후 시험 통과 자격증 발급시 8~10만원 정도 소요.
B20: 일감 얻는 경로 (플랫폼·기관 실명) | C20: 알바몬에 보면 여러 업체에서 블로그. SNS 전담 운영자를 모집중이며, 숨고나 크몽 등 직영플랫폼을 활용하여 자신의 경력이나 관련경험을 소개하며 일감을 직접 수주하는 방식으로 수익창출 가능
B21: ⑥ N잡 적합성 검증
B22: 10조건 | C22: ①시간 유연성 | D22: ②체력 감당 | E22: ③직업 이미지 | F22: ④재미 | G22: ⑤전문성 축적 | H22: ⑥일한 만큼 이상 수익 | I22: ⑦우상향 수익 | J22: ⑧충분한 수요 | K22: ⑨진입 가능성 | L22: ⑩직업적 자부심
B23: 판정 ○ △ ✕ | C23: ○ | D23: ○ | E23: ○ | F23: ○ | G23: ○ | H23: ○ | I23: ○ | J23: ○ | K23: ○ | L23: ○
B24: 판정 근거 (△·✕ 위주로) | C24: 실제 해당직업 구인 광고가 많아 글쓰기 재주와 꾸준함만 있다면 어렵지 않게 업체에 취업하는 형태로 일자리를 얻을 수 있음. 본인 노하우가 쌓이면 독립하여 크몽이나 숨고 등을 통해 일감을 계약해 보다 유연하게 작업 가능
B25: 종합 판정 | C25: 적합 | E25: 모두 o로 적합 판정
B26: ⑦ 실제 종사자 (1명)
B27: 이름 · 소속 · 경력 | C27: 한결마케팅 / 7년간 기업 마케팅 팀장 근무 / 본인 학원, 독서실 운영 경험
B28: 확인 출처 (기사·인터뷰·블로그·유튜브·플랫폼 프로필 등) | C28: 업종별 마케팅, 검색 최적화(SEO) 전문가 한결마케팅 - 크몽
B29: 컨택 포인트 (연락처·이메일·SNS·소속 기관) | C29: 0504-0901-1116 /크몽페이지에서도 질의 가능
B30: 인터뷰 가능성 | C30: 하 | E30: 블로그 운영대행 의뢰가 아니기 때문에 서면인터뷰를 요청하는 문의에 답변할지 미지수
B31: ⑧ 참고 URL (오른쪽 끝 칸 = 확인일)
B32: URL ① | C32: https://kmong.com/gig/507681 크몽 : 블로그 운영대행 27만원
B33: URL ② | C33: https://kmong.com/gig/759059#194 크몽 : 인스타, 틱톡 등 계정 세팅 및 운영대행 120만원~300만원
B34: URL ③ | C34: https://www.albamon.com/jobs/detail/119108999 유건컴퍼니 유튜브, 인스타, 블로그 운영 및 계정관리 담당자 모집
B35: URL ④ | C35: https://www.albamon.com/jobs/detail/118954300 보룡약국 쿠팡, 스마트스토어, 블로그 운영직원 구인
B36: URL ⑤ | C36: https://blog.naver.com/newjin14/224395865778 https://www.secondsalary.co.kr/news/articleView.html?idxno=55
B38: ※ 연노랑 칸에 입력합니다. L열은 확인일입니다.

Sheet 003_온라인 사무지원 프리랜서
B2: Job No. 003 온라인 사무지원 프리랜서
B3: 1. 디지털·AI 실무형 | 워크위즈 N잡스쿨 · 잡별 시장조사 시트
B5: ① 기본 정보
B6: 직업명 · 별칭 | C6: 온라인 사무지원 프리랜서
B7: 한 줄 소개 (30자 내외)
B8: 수집 상태 · 담당자 | C8: 미착수
B9: ② 핵심 지표 6종
B10: 지표 | C10: 초기비용 | D10: 월수익(만원) | E10: 성장성 | F10: 진입난이도 | G10: 주간 소요시간 | H10: 체력부담 | I10: 지표 근거 · 비고
B11: 값
B12: ③ 하는 일
B13: 하는 일 (3줄 요약)
B14: ④ 일자리 수요 근거
B15: 수요처 유형 · 규모 · 증감 추세
B16: 뒷받침 근거
B17: ⑤ 진입 방법
B18: 필요 자격 · 교육
B19: 초기 준비물 · 비용
B20: 일감 얻는 경로 (플랫폼·기관 실명)
B21: ⑥ N잡 적합성 검증
B22: 10조건 | C22: ①시간 유연성 | D22: ②체력 감당 | E22: ③직업 이미지 | F22: ④재미 | G22: ⑤전문성 축적 | H22: ⑥일한 만큼 이상 수익 | I22: ⑦우상향 수익 | J22: ⑧충분한 수요 | K22: ⑨진입 가능성 | L22: ⑩직업적 자부심
B23: 판정 ○ △ ✕
B24: 판정 근거 (△·✕ 위주로)
B25: 종합 판정
B26: ⑦ 실제 종사자 (1명)
B27: 이름 · 소속 · 경력 | C27: 한성아이디 인테리어업체 내 수리홈즈(A/S 전담부서) 중년 여직원
B28: 확인 출처 (기사·인터뷰·블로그·유튜브·플랫폼 프로필 등)
B29: 컨택 포인트 (연락처·이메일·SNS·소속 기관) | C29: 010-6625-1876
B30: 인터뷰 가능성 | C30: 중
B31: ⑧ 참고 URL (오른쪽 끝 칸 = 확인일)
B32: URL ①
B33: URL ②
B34: URL ③
B35: URL ④
B36: URL ⑤
B38: ※ 연노랑 칸에 입력합니다. L열은 확인일입니다.

Sheet 004_숏폼 영상 편집자
B2: Job No. 004 숏폼 영상 편집자
B3: 1. 디지털·AI 실무형 | 워크위즈 N잡스쿨 · 잡별 시장조사 시트
B5: ① 기본 정보
B6: 직업명 · 별칭 | C6: 숏폼 영상 편집자
B7: 한 줄 소개 (30자 내외) | C7: SNS용 짧은 영상을 빠르게 만들고 반복해서 의뢰받아 돈을 버는 직업
B8: 수집 상태 · 담당자 | C8: 수집중 | E8: 박나경
B9: ② 핵심 지표 6종
B10: 지표 | C10: 초기비용 | D10: 월수익(만원) | E10: 성장성 | F10: 진입난이도 | G10: 주간 소요시간 | H10: 체력부담 | I10: 지표 근거 · 비고
B11: 값 | C11: ₩₩ 50~300만 | D11: 30~100만원 | E11: ↗↗ 높음 | F11: ★★ | G11: 주 15~30시간 | H11: 하 | I11: 초기 : 건당 1만원~2만원, 월 50만원 이하 경력 프리랜서 : 반복고객, 월 계약 등으로 월 150만원 전문 편집자 : 고단가 광고, 정기계약 등으로 350만원~
B12: ③ 하는 일
B13: 하는 일 (3줄 요약) | C13: 원본 영상 편집 : 인터뷰, 강의, 팟캐스트 등 긴 영상의 핵심부분을 골라 15~60초 정도의 영상으로 만듬 소상공인 홍보영상 제작 : 음식점, 미용실, 병원, 온라인 브랜드 등의 제품이나 서비스를 홍보하는 영상 제작 채널 운영용 콘텐츠 정기 납품 : 매달 8~30개 등 일정 수량의 영상을 만들어 납품
B14: ④ 일자리 수요 근거
B15: 수요처 유형 · 규모 · 증감 추세 | C15: 개인 크리에이터들의 쇼츠나 하일라이트 영상 촬영, 제작/ 광고 대행사로부터 외주계약 / 온라인 쇼핑몰이나 일반기업 홍보부서 근무 / 지역 소상공인들의 홍보영상 촬영 제작/ 방송, 미디어, 교육업체의 방송클립 재가공 담당자로 취업 나스미디어는 글로벌 숏폼 산업 성장 가능성을 2021년 60조원에서 2026년 187조원으로 예상.
B16: 뒷받침 근거 | C16: 플랫폼 거래량 | E16: 『2025~2035 정성적 일자리 전망』 발간 | 고용노동부 > 뉴스·소식 > 보도·설명 > 보도자료
B17: ⑤ 진입 방법
B18: 필요 자격 · 교육 | C18: 편집도구 활용능력이 중요하므로 무료 온오프라인 강의나 고용24 등의 영상편집 제작 관련 훈련 적극 활용 단순 편집보다는 영상 기획력, 시청자가 관심을 끄는 구성, 브랜드별 스타일 차이 부각 까지 할 수 있는 편집자가 유리
B19: 초기 준비물 · 비용 | C19: 영상편집용 컴퓨터(100만원), 편집 프로그램(구독료 월 10만원), 관련교육 수강료(10~50만원), 저장장치(외장 SSD 등 8만~20만원)
B20: 일감 얻는 경로 (플랫폼·기관 실명) | C20: 크몽, 숨고, 위시켓 등에서 숏폼 편집 서비스 등록 / 사람인, 잡코리아 등 채용사이트에서 숏폼 편집자, 영상 콘텐츠 제작자 검색, 지원 / 마케팅 대행사에 외주 편집자로 지원
B21: ⑥ N잡 적합성 검증
B22: 10조건 | C22: ①시간 유연성 | D22: ②체력 감당 | E22: ③직업 이미지 | F22: ④재미 | G22: ⑤전문성 축적 | H22: ⑥일한 만큼 이상 수익 | I22: ⑦우상향 수익 | J22: ⑧충분한 수요 | K22: ⑨진입 가능성 | L22: ⑩직업적 자부심
B23: 판정 ○ △ ✕ | C23: ○ | D23: ○ | E23: ○ | F23: ○ | G23: ○ | H23: △ | I23: △ | J23: ○ | K23: ○ | L23: △
B24: 판정 근거 (△·✕ 위주로) | C24: 현실적으로 영상편집 실력이 좋은 20~30대 편집자들과 제작속도, 완성도 등 경쟁해야 하므로 중장년이 제작단가를 높이거나 우상향 수익을 확정할 수 없음. 또한 숏폼 제작 AI 들이 등장하고 있어 향후 수익화 어려울 가능성. 편집이 직업적 자부심을 준다고도 보기 어려움
B25: 종합 판정 | C25: 적합 | E25: X가 없어 적합 판정
B26: ⑦ 실제 종사자 (1명)
B27: 이름 · 소속 · 경력
B28: 확인 출처 (기사·인터뷰·블로그·유튜브·플랫폼 프로필 등)
B29: 컨택 포인트 (연락처·이메일·SNS·소속 기관)
B30: 인터뷰 가능성
B31: ⑧ 참고 URL (오른쪽 끝 칸 = 확인일)
B32: URL ① | C32: https://www.albamon.com/jobs/detail/119869597?searchRow=11&searchKeyword=%EC%98%81%EC%83%81%20%ED%8E%B8%EC%A7%91&productCount=1&logpath=1&sc=508 시급 15000원
B33: URL ② | C33: https://www.albamon.com/total-search?keyword=%EC%88%8F%ED%8F%BC%20%EC%A0%9C%EC%9E%91 | L33: 건별 9만원
B34: URL ③ | C34: https://biz.heraldcorp.com/article/10908079?ref=naver
B35: URL ④ | C35: https://www.enetnews.co.kr/news/articleView.html?idxno=48426
B36: URL ⑤ | C36: https://www.artmore.kr/sub/recruit/search_view.do?rec_idx=94911
B38: ※ 연노랑 칸에 입력합니다. L열은 확인일입니다.

Sheet 005_데이터 라벨러
B2: Job No. 005 데이터 라벨러
B3: 1. 디지털·AI 실무형 | 워크위즈 N잡스쿨 · 잡별 시장조사 시트
B5: ① 기본 정보
B6: 직업명 · 별칭 | C6: 데이터 라벨러
B7: 한 줄 소개 (30자 내외) | C7: 인공지능이 스스로 학습할 수 있도록 원시데이터에 태그를 달아주는 작업
B8: 수집 상태 · 담당자 | C8: 완료 | E8: 박나경
B9: ② 핵심 지표 6종
B10: 지표 | C10: 초기비용 | D10: 월수익(만원) | E10: 성장성 | F10: 진입난이도 | G10: 주간 소요시간 | H10: 체력부담 | I10: 지표 근거 · 비고
B11: 값 | C11: ₩ 50만 미만 | D11: 200만원 | E11: ↗ 보통 | F11: ★ | G11: 주 15~30시간 | H11: 하
B12: ③ 하는 일
B13: 하는 일 (3줄 요약) | C13: AI가 학습 데이터를 인식하도록 데이터의 특징을 정의하거나 수정하는 역할. 사진이나 영상 속 객체(사람, 자동차 등)의 외곽선을 네모 박스로 감싸 위치를 지정하는 작업/ 사진이 무엇인지(고양이, 쥐 등) 이름표를 붙이는 작업/ 의료 AI나 자율주행 AI 등을 위해 객체의 모양을 따라 정교하게 선을 따내는 작업/ 챗봇을 위한 질의응답 말뭉치 구축, 음성인식 AI를 위한 받아쓰기나 감정 라벨링 등의 역할 수행
B14: ④ 일자리 수요 근거
B15: 수요처 유형 · 규모 · 증감 추세 | C15: 국내 AI 시장이 거대 언어모델과 생성형 위주로 폭발적으로 성장중인 가운데 AI성능의 80% 이상은 데이터 품질이 결정하므로, 이를 정교하게 가공할 인력의 수요는 꾸준함. 누구나 할 수 있는 단순 반복 업무가 많음. 라벨링 자동화 기술이 발전하고 있지만 여전히 사람이 최종 확인해야하는 단계가 필수적이라 당분간은 수요가 있음. 다만 단순 노동형 일자리는 점차 숙련도가 높은 쪽으로 재편될 가능성.
B16: 뒷받침 근거 | C16: 법제도·정책 | E16: https://www.dailysecu.com/news/articleView.html?idxno=208256
B17: ⑤ 진입 방법
B18: 필요 자격 · 교육 | C18: 지자체 여성인력개발센터 또는 중장년일자리지원센터, 서울시50플러스 등에서 데이터라벨러 양성과정(보통 2개월)을 주기적으로 개설중 / 데이터라벨링 전문기업인 클라우드웍스 등에서도 교육과정을 운영/
B19: 초기 준비물 · 비용 | C19: 지자체 무료 교육이 많아 초기 비용은 거의 들지 않음
B20: 일감 얻는 경로 (플랫폼·기관 실명) | C20: 에이아이웍스, 클라우드웍스 등에서 데이터라벨러 모집 공고가 수시로 뜸. 알바몬이나 사람인 등에서 데이터라벨링으로 검색하면 포티투닷(자율주행 데이터), 알체라(비대면 본인인증 서비스) 등과 같은 기업에서 데이터 라벨링, 가공, 검수자를 지속 모집
B21: ⑥ N잡 적합성 검증
B22: 10조건 | C22: ①시간 유연성 | D22: ②체력 감당 | E22: ③직업 이미지 | F22: ④재미 | G22: ⑤전문성 축적 | H22: ⑥일한 만큼 이상 수익 | I22: ⑦우상향 수익 | J22: ⑧충분한 수요 | K22: ⑨진입 가능성 | L22: ⑩직업적 자부심
B23: 판정 ○ △ ✕ | C23: ○ | D23: ○ | E23: △ | F23: △ | G23: ○ | H23: △ | I23: △ | J23: ○ | K23: ○ | L23: △
B24: 판정 근거 (△·✕ 위주로) | C24: 초기 진입이 비교적 쉽고 알바 자리를 많이 뽑고 있으나 초보는 건당 100원~300원 단위로 페이가 주어져 노동대비 수익이 낮음. 그러나 이 고비를 넘기고, 꾸준하게 공개모집 프로젝트에 참여하거나, 데이터라벨링 기업에 프로젝트성 단기 취업하게 된다면 안정적으로 월 220만원 이상의 월급을 받을 수 있음
B25: 종합 판정 | C25: 적합 | E25: 꾸준한 수입을 얻기는 어려울 수 있으나 일감이 있을 때에는 경력자가 확실한 우위를 점할 수 있어 N잡의 한 갈래로 갖고 가기에 적합
B26: ⑦ 실제 종사자 (1명)
B27: 이름 · 소속 · 경력 | C27: 서유진 / aiworks / 5년
B28: 확인 출처 (기사·인터뷰·블로그·유튜브·플랫폼 프로필 등) | C28: 강남 신중년센터 ai데이터라벨러 강사로 만남. 수상생들에게 데이터라벨링 일자리를 몇개 소개해주시기도 함. 본인을 n잡러라고 소개
B29: 컨택 포인트 (연락처·이메일·SNS·소속 기관) | C29: 010-3042-7176 dbwls403@naver.com
B30: 인터뷰 가능성 | C30: 상 | E30: 직접 연락했고 서면 인터뷰 가능하다는 답변 받음
B31: ⑧ 참고 URL (오른쪽 끝 칸 = 확인일)
B32: URL ① | C32: https://www.dailysecu.com/news/articleView.html?idxno=208257 | L32: 26.8
B33: URL ② | C33: https://www.wikitree.co.kr/articles/1155878 | L33: 26.8
B34: URL ③ | C34: https://www.hansbiz.co.kr/news/articleView.html?idxno=860536 | L34: 26.8
B35: URL ④ | C35: https://biz.heraldcorp.com/article/10822732?ref=naver | L35: 26.7
B36: URL ⑤ | C36: https://www.albamon.com/total-search?keyword=%EB%8D%B0%EC%9D%B4%ED%84%B0%EB%9D%BC%EB%B2%A8%EB%A7%81 | L36: 26.8
B38: ※ 연노랑 칸에 입력합니다. L열은 확인일입니다.

Sheet 006_앱 사용성 평가원
B2: Job No. 006 앱 사용성 평가원
B3: 1. 디지털·AI 실무형 | 워크위즈 N잡스쿨 · 잡별 시장조사 시트
B5: ① 기본 정보
B6: 직업명 · 별칭 | C6: 앱 사용성 평가원
B7: 한 줄 소개 (30자 내외)
B8: 수집 상태 · 담당자 | C8: 미착수
B9: ② 핵심 지표 6종
B10: 지표 | C10: 초기비용 | D10: 월수익(만원) | E10: 성장성 | F10: 진입난이도 | G10: 주간 소요시간 | H10: 체력부담 | I10: 지표 근거 · 비고
B11: 값
B12: ③ 하는 일
B13: 하는 일 (3줄 요약)
B14: ④ 일자리 수요 근거
B15: 수요처 유형 · 규모 · 증감 추세
B16: 뒷받침 근거
B17: ⑤ 진입 방법
B18: 필요 자격 · 교육
B19: 초기 준비물 · 비용
B20: 일감 얻는 경로 (플랫폼·기관 실명)
B21: ⑥ N잡 적합성 검증
B22: 10조건 | C22: ①시간 유연성 | D22: ②체력 감당 | E22: ③직업 이미지 | F22: ④재미 | G22: ⑤전문성 축적 | H22: ⑥일한 만큼 이상 수익 | I22: ⑦우상향 수익 | J22: ⑧충분한 수요 | K22: ⑨진입 가능성 | L22: ⑩직업적 자부심
B23: 판정 ○ △ ✕
B24: 판정 근거 (△·✕ 위주로)
B25: 종합 판정
B26: ⑦ 실제 종사자 (1명)
B27: 이름 · 소속 · 경력
B28: 확인 출처 (기사·인터뷰·블로그·유튜브·플랫폼 프로필 등)
B29: 컨택 포인트 (연락처·이메일·SNS·소속 기관)
B30: 인터뷰 가능성
B31: ⑧ 참고 URL (오른쪽 끝 칸 = 확인일)
B32: URL ①
B33: URL ②
B34: URL ③
... B38: ※ 연노랑 칸에 입력합니다. L열은 확인일입니다.

Sheet 007_상세페이지 디자이너
B2: Job No. 007 상세페이지 디자이너
B3: 1. 디지털·AI 실무형 | 워크위즈 N잡스쿨 · 잡별 시장조사 시트
B5: ① 기본 정보
B6: 직업명 · 별칭 | C6: 상세페이지 디자이너
B7: 한 줄 소개 (30자 내외) | C7: 쇼핑몰 상품을 더 잘 이해하고 사고 싶게 만드는 웹페이지를 만드는 일
B8: 수집 상태 · 담당자 | C8: 완료 | E8: 박나경
B9: ② 핵심 지표 6종
B10: 지표 | C10: 초기비용 | D10: 월수익(만원) | E10: 성장성 | F10: 진입난이도 | G10: 주간 소요시간 | H10: 체력부담 | I10: 지표 근거 · 비고
B11: 값 | C11: ₩ 50만 미만 | D11: 220만원 | E11: → 정체 | F11: ★★★ | G11: 주 15~30시간 | H11: 하 | I11: https://www.albamon.com/total-search?keyword=%EC%83%81%ED%92%88%20%ED%8E%98%EC%9D%B4%EC%A7%80%20%EC%A0%9C%EC%9E%91&type=SKL
B12: ③ 하는 일
B13: 하는 일 (3줄 요약) | C13: 상품 특징, 경쟁 제품, 타깃 고객을 조사하고 핵심 장점을 정리 / 고객이 어떤 정보를 알아야 구매할지 순서를 설계 / 제품 누끼 작업, 색상 보정, 합성, 이미지 연출 등 진행. 촬영을 추가하기도 함 / 상품 사진, 문구, 아이콘, 색상, 글꼴을 조합해 상세페이지를 제작 / 쇼핑몰 메인 배너, 상품 썸네일, 할인 행사 이미지 등을 만들기도 함 / 브랜드의 여러 상품 페이지를 통일된 스타일로 제작하고, 신제품 출시 때마다 디자인을 추가
B14: ④ 일자리 수요 근거
B15: 수요처 유형 · 규모 · 증감 추세 | C15: 온라인 쇼핑몰, 스마트스토어 사업자 등으로부터 소규모 제작 의뢰를 받을 수 있음 / 온라인 유통, 이커머스 기업들의 상품 등록, 콘텐츠 디자인 의뢰 수요가 꾸준함 / 화장품, 식품, 패션 브랜드의 신제품 페이지나 브랜드 콘텐츠 제작 수요도 늘 있음 온라인 판매 채널이 다양하고 브랜드간 경쟁이 치열해 비슷한 상품사이 차별점을 보여주기 위한 콘텐츠 제작 수요는 꾸준. AI로 인해 기본적인 이미지 배치나 디자인으로는 점점 수익화가 어려울 가능성
B16: 뒷받침 근거 | C16: 복합
B17: ⑤ 진입 방법
B18: 필요 자격 · 교육 | C18: 포토샵, 일러스트레이터, 캔바 등 실무 제작 디자인툴 사용법을 익혀야 함.
B19: 초기 준비물 · 비용 | C19: 가상의 상품 3개 정도 선정해 다른 컨셉으로 상세페이지를 제작한 포트폴리오 준비. 디자인 프로그램(5~8만원) 구독, 기초강의(20~30만원) 수강 등 초기 투자비용 10~50만원 소요
B20: 일감 얻는 경로 (플랫폼·기관 실명) | C20: 크몽에 상세페이지 제작 서비스를 상품으로 등록 / 숨고에 고객 요청에 맞춰 견적 제시 / 사람인, 잡코리아, 알바몬 등 채용정보사이트에 상세페이지 디자이너, 이커머스 디자이너, 쇼핑몰 콘텐츠 디자이너 등으로 검색 / 인스타, 블로그 등에 작업 과정을 공개하며 의뢰 수주
B21: ⑥ N잡 적합성 검증
B22: 10조건 | C22: ①시간 유연성 | D22: ②체력 감당 | E22: ③직업 이미지 | F22: ④재미 | G22: ⑤전문성 축적 | H22: ⑥일한 만큼 이상 수익 | I22: ⑦우상향 수익 | J22: ⑧충분한 수요 | K22: ⑨진입 가능성 | L22: ⑩직업적 자부심
B23: 판정 ○ △ ✕ | C23: ○ | D23: ○ | E23: ○ | F23: ○ | G23: ○ | H23: △ | I23: △ | J23: ○ | K23: ○ | L23: △
B24: 판정 근거 (△·✕ 위주로) | C24: 상세페이지 디자이너는 숏폼 제작자와 마찬가지로 디자인툴 숙련도가 더 나은 젊은 세대와 경쟁한다는 점에서 우상향 수익이나 일한만큼 이상의 수익이 확실치 않음. 그러나 건당 업무를 맡아 큰 시간 제약없이 다른 N잡과 병행하기 용이
B25: 종합 판정 | C25: 적합 | E25: X가 없어 적합 판정
B26: ⑦ 실제 종사자 (1명)
B27: 이름 · 소속 · 경력 | C27: 디자인몽땅 크몽 상위 2% 전문가, 웹에이전시 디자인팀 7년, 프리덴 소파 디자인팀 1.2년, 프리랜서 10년
B28: 확인 출처 (기사·인터뷰·블로그·유튜브·플랫폼 프로필 등) | C28: https://kmong.com/gig/541284
B29: 컨택 포인트 (연락처·이메일·SNS·소속 기관) | C29: UI/UX 디자인, 마케팅 디자인 전문가 디자인몽땅 - 크몽
B30: 인터뷰 가능성
B31: ⑧ 참고 URL (오른쪽 끝 칸 = 확인일)
B32: URL ① | C32: https://www.albamon.com/jobs/detail/119709133?searchRow=1&searchKeyword=%EC%98%81%EC%83%81%20%ED%8E%B8%EC%A7%91&productCount=2&logpath=1&sc=508 시급 15000원
B33: URL ② | C33: https://www.albamon.com/total-search?keyword=%EC%83%81%ED%92%88%20%ED%8E%98%EC%9D%B4%EC%A7%80%20%EC%A0%9C%EC%9E%91&type=SKL
B34: URL ③ | C34: https://www.albamon.com/jobs/detail/502063506
B35: URL ④ | C35: https://www.jobkorea.co.kr/Search/?stext=%EC%83%81%ED%92%88%ED%8E%98%EC%9D%B4%EC%A7%80%EC%9E%91%EC%97%85&FeatureCode=SKL&tabType=recruit | L35: 연봉 2600만원
B36: URL ⑤ | C36: https://www.saramin.co.kr/zf_user/jobs/relay/view?rec_idx=55165153&view_type=search
B38: ※ 연노랑 칸에 입력합니다. L열은 확인일입니다.

Sheet 008_유해콘텐츠 모니터링 요원
B2: Job No. 008 유해콘텐츠 모니터링 요원
B3: 1. 디지털·AI 실무형 | 워크위즈 N잡스쿨 · 잡별 시장조사 시트
B5: ① 기본 정보
B6: 직업명 · 별칭 | C6: 유해콘텐츠 모니터링 요원
B7: 한 줄 소개 (30자 내외)
B8: 수집 상태 · 담당자 | C8: 미착수
B9: ② 핵심 지표 6종
B10: 지표 | C10: 초기비용 | D10: 월수익(만원) | E10: 성장성 | F10: 진입난이도 | G10: 주간 소요시간 | H10: 체력부담 | I10: 지표 근거 · 비고
B11: 값
B12: ③ 하는 일
B13: 하는 일 (3줄 요약)
B14: ④ 일자리 수요 근거
B15: 수요처 유형 · 규모 · 증감 추세
B16: 뒷받침 근거
B17: ⑤ 진입 방법
B18: 필요 자격 · 교육
B19: 초기 준비물 · 비용
B20: 일감 얻는 경로 (플랫폼·기관 실명)
B21: ⑥ N잡 적합성 검증
B22: 10조건 | C22: ①시간 유연성 | D22: ②체력 감당 | E22: ③직업 이미지 | F22: ④재미 | G22: ⑤전문성 축적 | H22: ⑥일한 만큼 이상 수익 | I22: ⑦우상향 수익 | J22: ⑧충분한 수요 | K22: ⑨진입 가능성 | L22: ⑩직업적 자부심
B23: 판정 ○ △ ✕
B24: 판정 근거 (△·✕ 위주로)
B25: 종합 판정
B26: ⑦ 실제 종사자 (1명)
B27: 이름 · 소속 · 경력
B28: 확인 출처 (기사·인터뷰·블로그·유튜브·플랫폼 프로필 등)
B29: 컨택 포인트 (연락처·이메일·SNS·소속 기관)
B30: 인터뷰 가능성
B31: ⑧ 참고 URL (오른쪽 끝 칸 = 확인일)
B32: URL ①
B33: URL ②
B34: URL ③
... B38: ※ 연노랑 칸에 입력합니다. L열은 확인일입니다.

Sheet 009_경영 컨설턴트
B2: Job No. 009 경영 컨설턴트
B3: 2. 경영·창업 자문형 | 워크위즈 N잡스쿨 · 잡별 시장조사 시트
B5: ① 기본 정보
B6: 직업명 · 별칭 | C6: 경영 컨설턴트
B7: 한 줄 소개 (30자 내외) | C7: 기업의 여러 분야 경영 문제를 진단하고 개선 방안을 제시하는 일
B8: 수집 상태 · 담당자 | C8: 완료 | E8: 담당 : 정재웅
B9: ② 핵심 지표 6종
B10: 지표 | C10: 초기비용 | D10: 월수익(만원) | E10: 성장성 | F10: 진입난이도 | G10: 주간 소요시간 | H10: 체력부담 | I10: 지표 근거 · 비고
B11: 값 | C11: ₩₩ 50~300만 | D11: 100~300 | E11: ↗ 보통 | F11: ★★★★★ | G11: 주 5~15시간 | H11: 하 | I11: - 겸업 컨설턴트 : 150~300만원/월 (공공 및 민간기업 자문) - 전업 컨설턴트 : 300~700만원/월(프리랜서), 500~800만원/월(컨설팅펌/상주 전문위원)"
B12: ③ 하는 일
B13: 하는 일 (3줄 요약) | C13: - 경영 진단 및 문제 분석: 기업의 재무, 마케팅, 인사 등 전반적인 운영 상태를 객관적으로 분석하여 핵심 원인과 비효율 요소를 도출 - 전략 수립 및 해결책 제안: 분석된 데이터를 바탕으로 기업의 성장을 위한 중장기 사업 전략, 신사업 진출 방안, 비용 절감 등의 솔루션 제공 - 실행 지원 및 변화 관리: 제안된 전략이 현업에 잘 안착할 수 있도록 프로세스 개선하고, 조직 구조 개편 및 임직원 교육 등 변화 관리 지원
B14: ④ 일자리 수요 근거
B15: 수요처 유형 · 규모 · 증감 추세 | C15: - 수요처 : 대기업 및 중견그룹 전략·혁신 조직. 정부 산하 기관 및 공공 공기업, 창업보육센터 및 벤처캐피털(VC) · 액셀러레이터 - 시장 규모 : 국내 전체 경영컨설팅 시장(약 6조 원 이상) 중, 시니어 및 파트너급 전문 자문 영역은 시장의 약 40~50% (약 2조 5천억~3조원) - 증감 추세 : 지속적으로 우상향 (고물가·고환율 등 복합 경제 위기와 급격한 기술 변화(AI·DX)라는 환경)
B16: 뒷받침 근거 | C16: 복합 | E16: - 대기업 및 중견기업, 정부 산하기관 및 공공 공기업, 창업보육센터 및 벤처캐피털, 엑셀러레이터 등
B17: ⑤ 진입 방법
B18: 필요 자격 · 교육 | C18: - 경력 : 재무, 인사, IT, 제조, 연구개발 등 분야에서 10년 이상 현업 경력 - 자격증 : 경영지도사 및 기술지도사, 국제 공인 경영컨설턴트(CMC): 국제컨설팅협회(ICMCI) - 교육 : 1) 민간·기관 인증 컨설턴트 과정: 한국능률협회컨설팅(KMAC)이나 한국생산성본부(KPC) 2) 시니어 및 엑셀러레이터 특화 과정: 시니어 전문 액셀러레이터 및 컨설턴트 양성 과정 (예: 지자체·투자사 연계 프로그램)
B19: 초기 준비물 · 비용 | C19: - 초기 자본 (지식 서비스업 특성): 100만 원 미만~수백만원 수준 최소 자본. 개인 노트북, 전문 오피스 소프트웨어, 명함 및 프로필 제작 비용 - 사무실 및 인프라 비용: 초기에는 독립 사무실 대신, 소상공인진흥공단이나 지자체에서 운영하는 창업보육센터, 공유오피스(월 20~50만 원) 사용
B20: 일감 얻는 경로 (플랫폼·기관 실명) | C20: - 정부 및 공공기관 지원 사업: 중소벤처기업부, 중소기업중앙회, 각 지자체 및 테크노파크가 주관 기관 등에 전문 위원으로 등록. - 유관기관 및 산학협력 기관(창조경제혁신센터, 테크노파크, 각 대학 산학협력단, 소상공인시장진흥공단 등) 전문가(멘토·컨설턴트) 인력 풀 등록 - 전문 네트워크 및 헤드헌팅 플랫폼: B2B 전문가 네트워크 플랫폼(예: 타이거컴퍼니, 로켓펀치 등 국내외 링크드인 및 프리미엄 자문 플랫폼)에 등록 - 지인 영업 및 업계 다이렉트 네트워킹: 이전 직장 경력, 기존 비즈니스 네트워크(산업계 지인, 거래처), 중소기업 CEO 모임이나 세미나 참석
B21: ⑥ N잡 적합성 검증
B22: 10조건 | C22: ①시간 유연성 | D22: ②체력 감당 | E22: ③직업 이미지 | F22: ④재미 | G22: ⑤전문성 축적 | H22: ⑥일한 만큼 이상 수익 | I22: ⑦우상향 수익 | J22: ⑧충분한 수요 | K22: ⑨진입 가능성 | L22: ⑩직업적 자부심
B23: 판정 ○ △ ✕ | C23: ○ | D23: ○ | E23: ○ | F23: △ | G23: ○ | H23: ○ | I23: ○ | J23: △ | K23: △ | L23: ○
B24: 판정 근거 (△·✕ 위주로) | C24: ④ △ — 컨설팅 대상 기업에서 성과가 날 때 재미가 있으나 그렇지 않은 경우 재미가 없을 수 있음. ⑧ △ — 컨설팅 성과 및 영업 역량에 따라 고객 수요가 유동적일 수 있음. ⑨ △ — 10년 이상 특정 분야에서 검증된 경력과 평판이 필요.
B25: 종합 판정 | C25: 적합 | E25: 10조건 중 7개 통과, 3개 조건부
B26: ⑦ 실제 종사자 (1명)
B27: 이름 · 소속 · 경력 | C27: - 장동철 / 컨설턴트 & 작가 / 현대차, 모비스 인사부문 경력 29년(부사장 은퇴), 현재 경영컨설턴트 (경력 4년) 및 도서 작가 (저서 2권)
B28: 확인 출처 (기사·인터뷰·블로그·유튜브·플랫폼 프로필 등) | C28: - 인터뷰 기사 (URL ①). 지식인사이드 인터뷰 동영상 (URL ②, 198만뷰), 간략 프로필과 저서 소개 (URL ③) - 저서 : <완생, 좋은 삶을 위한 성공의기술(2024, 공저)>, <제법 괜찮은 리더가 되고픈 당신에게(2022)> 도서 저자
B29: 컨택 포인트 (연락처·이메일·SNS·소속 기관) | C29: - Email : just6392@naver.com
B30: 인터뷰 가능성 | C30: 중 | E30: - 대기업 및 중소기업 등 HR 및 리더십 분야 강사 경험이 풍부한데 많이 사양하는 편임 (현대차 입사 동기)
B31: ⑧ 참고 URL (오른쪽 끝 칸 = 확인일)
B32: URL ① | C32: https://publy.co/content/7746?fr=profile
B33: URL ② | C33: https://www.youtube.com/watch?v=kP5H1p4ZPnw
B34: URL ③ | C34: https://www.aladin.co.kr/author/wauthor_overview.aspx?AuthorSearch=@9068189
B35: URL ④
B36: URL ⑤
B38: ※ 연노랑 칸에 입력합니다. L열은 확인일입니다.

Sheet 010_소상공인 컨설턴트
B2: Job No. 010 소상공인 컨설턴트
B3: 2. 경영·창업 자문형 | 워크위즈 N잡스쿨 · 잡별 시장조사 시트
B5: ① 기본 정보
B6: 직업명 · 별칭 | C6: 소상공인 컨설턴트
B7: 한 줄 소개 (30자 내외) | C7: 동네 가게와 소상공인의 매출·운영 문제를 현장에서 진단하고 해결을 돕는 일
B8: 수집 상태 · 담당자 | C8: 완료 | E8: 담당 : 정재웅
B9: ② 핵심 지표 6종
B10: 지표 | C10: 초기비용 | D10: 월수익(만원) | E10: 성장성 | F10: 진입난이도 | G10: 주간 소요시간 | H10: 체력부담 | I10: 지표 근거 · 비고
B11: 값 | C11: ₩ 50만 미만 | F11: ★★★★ | G11: 주 5~15시간 | H11: 중
B12: ③ 하는 일
B13: 하는 일 (3줄 요약) | C13: - 경영 진단 및 분석 : 재무 상태, 손익 구조, 매장 운영 프로세스를 분석하여 문제점 파악 - 상권 및 입지 분석, 마케팅 및 홍보 전략, 매장 운영 효율화 등 지원 방안 강구 및 조언 - 정부 지원 사업 연계(소상공인시장진흥공단 등 공공 기관의 지원 정책, 자금 대출, 교육 프로그램 안내 및 신청 지원) - 사업 정리 및 재기 지원 : 폐업 예정이거나 재창업을 준비하는 소상공인을 위한 컨설팅 및 컨설팅 바우처 연계
B14: ④ 일자리 수요 근거
B15: 수요처 유형 · 규모 · 증감 추세 | C15: - 수요처 : 1) 유형일반 소상공인 및 예비 창업자: 요식업, 도소매업, 서비스업 등 생계형 및 독립 자영업자 2) 정부 및 공공기관 : 중소벤처기업부, 소상공인시장진흥공단(소진공), 지방자치단체 및 테크노파크 등 (주요 지원 사업의 수행 주체) 3) 프랜차이즈 가맹점주 : 본사 매뉴얼 적용, 가맹점 수익성 개선 및 노무·세무 자문 필요 집단 4) 재기 및 폐업 예정자 : 사업 정리, 철거 지원, 재창업 패키지 프로그램 참여 대상자 - 시장 규모 : 1) 국내 전체 경영 컨설팅 서비스 시장은 약 6조 원대 이상 규모로 추산. 연평균 8% 이상 성장하는 추세. 2) 소상공인 및 중소기업 대상 컨설팅 시장은 정부의 소상공인 디지털 전환 및 상권 활성화에 연동되어 연간 수천억원 이상의 규모. - 증감 추세 : 디지털 및 AI 전환 수요 급증 (키오스크·배달앱 알고리즘 활용, 온라인 마케팅 등 디지털 전환 컨설팅 수요가 빠르게 늘고 있음)
B16: 뒷받침 근거 | C16: 복합
B17: ⑤ 진입 방법
B18: 필요 자격 · 교육 | C18: - 필요 자격 (공공 및 정부사업 기준) : 1) 경영지도사 또는 기술지도사 등 국가 전문자격증 소지자자격 소지자 2) 학력 및 경력 요건:관련 학과 석사 학위 이상 취득 후, 소상공인 관련 컨설팅 및 교육 실무 경력 보통 3년 이상. 동일 업종 실무 경력 8년 이상, 대학의 창업·경영 관련 학과 겸임교수 또는 강사 경력자 - 교육 및 역량 : 중소벤처기업부 및 소상공인시장진흥공단(소진공) 등에서 주관하는 역량강화 사업의 풀(Pool)에 진입하기 위해 정해진 신규 컨설턴트 소양 및 직무 교육 수료 필요
B19: 초기 준비물 · 비용 | C19: - 노트북, 테블릿 PC 및 S/W, 자격 취득 및 교육 비용, 프로필 및 명함 등 영업 비용 (비용 150 ~ 350만원)
B20: 일감 얻는 경로 (플랫폼·기관 실명) | C20: - 공공기관 및 지원사업 (주 경로): 소상공인시장진흥공단(소진공) 및 중소벤처기업부가 주관하는 소상공인 역량 강화 사업 등의 컨설턴트 풀 등록 - 지자체(서울시, 경기도 및 기초자치단체)나 테크노파크에서 발주하는 지역 소상공인 지원 사업 입찰 및 수행기관 참여 - 오프라인 및 현장 영업 : 소상공인연합회, 지역 상인회, 전통시장 상인회와의 네트워킹을 통한 직접 상담 및 수주 관내 소상공인센터나 일자리센터 등 유관 기관과의 협력 관계 구축 - 온라인 브랜딩 및 마케팅 : 전문 블로그, 브런치, 링크드인(LinkedIn) 등을 통해 실제 경영 진단 및 매출 개선 성공 사례(포트폴리오) 발행
B21: ⑥ N잡 적합성 검증
B22: 10조건 | C22: ①시간 유연성 | D22: ②체력 감당 | E22: ③직업 이미지 | F22: ④재미 | G22: ⑤전문성 축적 | H22: ⑥일한 만큼 이상 수익 | I22: ⑦우상향 수익 | J22: ⑧충분한 수요 | K22: ⑨진입 가능성 | L22: ⑩직업적 자부심
B23: 판정 ○ △ ✕
B24: 판정 근거 (△·✕ 위주로)
B25: 종합 판정 | C25: 적합
B26: ⑦ 실제 종사자 (1명)
B27: 이름 · 소속 · 경력 | C27: - 윤정혜 대표 / (주)이노밸류 / 소상공인 컨설터트 20년 이상. 경영지도사, 컨설팅학 박사
B28: 확인 출처 (기사·인터뷰·블로그·유튜브·플랫폼 프로필 등)
B29: 컨택 포인트 (연락처·이메일·SNS·소속 기관) | C29: - E :
B30: 인터뷰 가능성 | C30: 상
B31: ⑧ 참고 URL (오른쪽 끝 칸 = 확인일)
B32: URL ①
B33: URL ②
B34: URL ③
B35: URL ④
B36: URL ⑤
B38: ※ 연노랑 칸에 입력합니다. L열은 확인일입니다.

Sheet 011_창업 멘토·컨설턴트
B2: Job No. 011 창업 멘토·컨설턴트
B3: 2. 경영·창업 자문형 | 워크위즈 N잡스쿨 · 잡별 시장조사 시트
B5: ① 기본 정보
B6: 직업명 · 별칭 | C6: 창업 멘토·컨설턴트
B7: 한 줄 소개 (30자 내외) | C7: 창업 준비자에게 아이템 검증부터 사업계획, 자금 조달까지 조언하는 일
B8: 수집 상태 · 담당자 | C8: 완료 | E8: 담당 : 정재웅
B9: ② 핵심 지표 6종
B10: 지표 | C10: 초기비용 | D10: 월수익(만원) | E10: 성장성 | F10: 진입난이도 | G10: 주간 소요시간 | H10: 체력부담 | I10: 지표 근거 · 비고
B11: 값 | C11: ₩ 50만 미만 | D11: 100~300 | E11: ↗ 보통 | F11: ★★★★ | G11: 주 5~15시간 | H11: 하 | I11: - 거래처 2~3곳 기준 100~300만원
B12: ③ 하는 일
B13: 하는 일 (3줄 요약) | C13: - 자격 : 기업 경영, 기술 개발, 투자 심사 등의 분야에서 수년간의 실무 경력이 필요. 경영지도사 자격증 필수. - 교육 : 중소벤처기업부 장관이 인정하는 창업기획자 전문인력 양성 교육과정(약 50시간) 수료하는 과정이 대표적.
B14: ④ 일자리 수요 근거
B15: 수요처 유형 · 규모 · 증감 추세 | C15: - 수요처 유형 : 1) 공공 및 지원기관 (창업진흥원, 중소벤처기업부 산하 기관, 전국 창조경제혁신센터, 테크노파크, 대학 산학협력단 등) 2) 민간 창업 생태계 (액셀러레이터(AC), 벤처캐피털(VC), 민간 창업보육센터, 공유오피스 입주 스타트업 등) 3) 개인 및 예비 창업자: 기술창업, 소상공소상공인 창업, 로컬 비즈니스, 글로벌 진출을 준비하는 예비·초기 창업자 - 시장 규모 : 정부 및 공공 멘토링 지원 예산 및 민간 시장을 감안시 매년 수천억원 규모 - 증감 추세 : 구조적으로 우상향하는 추세.
B16: 뒷받침 근거 | C16: 복합 | E16: - 연간 10만개 이상의 기술 및 일반 창업기업이 생기고 있고 정부의 스케일업 정책이 강화되고 있음 - AI 도입, 디지털 전환(DX), 글로벌 시장 진출의 니즈가 증가하며 시니어 창업멘토에 대한 필요성 급증
B17: ⑤ 진입 방법
B18: 필요 자격 · 교육 | C18: - 자격 : 기업 경영, 기술 개발, 투자 심사 등의 분야에서 수년간의 실무 경력이 필요. 경영지도사 자격증 필요. - 교육 : 중소벤처기업부 장관이 인정하는 창업기획자 전문인력 양성 교육과정(약 50시간)이 대표적 프로그램
B19: 초기 준비물 · 비용 | C19: - 노트북과 기본 S/W 외 50만원 내외 비용.(프로필 사진 쵤영 및 명함 인쇄 비용) - 공간 및 사무실 : 초기 홈오피스를 사용하거나 지자체의 창업보육센터의 공간 활용
B20: 일감 얻는 경로 (플랫폼·기관 실명) | C20: - K-Startup(창업진흥원) 및 공공 플랫폼, 한국창업멘토협회 및 유관 협회, 창조경제혁신센터 및 테크노파크 네트워크, 대학 산학협력단의 창업보육센터(BI) 등록 및 활동 - 민간 액셀러레이터(AC) 및 벤처캐피털(VC) 사들과 협력
B21: ⑥ N잡 적합성 검증
B22: 10조건 | C22: ①시간 유연성 | D22: ②체력 감당 | E22: ③직업 이미지 | F22: ④재미 | G22: ⑤전문성 축적 | H22: ⑥일한 만큼 이상 수익 | I22: ⑦우상향 수익 | J22: ⑧충분한 수요 | K22: ⑨진입 가능성 | L22: ⑩직업적 자부심
B23: 판정 ○ △ ✕ | C23: ○ | D23: ○ | E23: ○ | F23: ○ | G23: ○ | H23: △ | I23: △ | J23: ○ | K23: ○ | L23: ○
B24: 판정 근거 (△·✕ 위주로) | C24: ⑥ △ — 시즌적인 수요 및 소득의 증감이 있음 ⑦ △ — 전체적으로 증가하는 추세이나 변동 폭이 있음.
B25: 종합 판정 | C25: 적합 | E25: 10조건 중 8개 통과, 2개 조건부
B26: ⑦ 실제 종사자 (1명)
B27: 이름 · 소속 · 경력 | C27: - 김현주 대표 / 공감나무디자인연구소 / 창업컨설턴트 및 커리어 코칭 강사 8년차
B28: 확인 출처 (기사·인터뷰·블로그·유튜브·플랫폼 프로필 등) | C28: - 경력/이력 소개(URL①), 개인 블로그 (URL②)
B29: 컨택 포인트 (연락처·이메일·SNS·소속 기관) | C29: Email : khjchange@naver.com
B30: 인터뷰 가능성 | C30: 상 | E30: - 현재 상상우리에서 커리어 코칭 분야에서 강의하고 있는 상태.
B31: ⑧ 참고 URL (오른쪽 끝 칸 = 확인일)
B32: URL ① | C32: https://www.rocketpunch.com/@khjchange
B33: URL ② | C33: https://blog.naver.com/khjchange
B34: URL ③
B35: URL ④
B36: URL ⑤
B38: ※ 연노랑 칸에 입력합니다. L열은 확인일입니다.

Sheet 012_스타트업 액셀러레이터
B2: Job No. 012 스타트업 액셀러레이터
B3: 2. 경영·창업 자문형 | 워크위즈 N잡스쿨 · 잡별 시장조사 시트
B5: ① 기본 정보
B6: 직업명 · 별칭 | C6: 스타트업 액셀러레이터
B7: 한 줄 소개 (30자 내외) | C7: 초기 스타트업을 선발해 보육·멘토링하고 성장을 지원하는 일
B8: 수집 상태 · 담당자 | C8: 완료 | E8: 담당 : 정재웅
B9: ② 핵심 지표 6종
B10: 지표 | C10: 초기비용 | D10: 월수익(만원) | E10: 성장성 | F10: 진입난이도 | G10: 주간 소요시간 | H10: 체력부담 | I10: 지표 근거 · 비고
B11: 값 | C11: ₩₩ 50~300만 | D11: 100~400 | E11: ↗ 보통 | F11: ★★★★★ | G11: 주 15~30시간 | H11: 하 | I11: - 비상근 멘토 / 전문위원(시니어 자문) : 월 100 ~ 400만원 - AC 법인 파트너/상근 심사역 : 월 400 ~700만원
B12: ③ 하는 일
B13: 하는 일 (3줄 요약) | C13: - 극초기 자금 투입 및 지분 투자, 후속 투자 유치 지원 (데모데이) 및 정부 지원 사업 연계 - 밀착 멘토링 및 실전 액셀러레이팅 프로그램 운영 - 국내 및 해외 네트워킹 구축 및 사업화 인프라(사무 공간, 해외 지사 등) 제공
B14: ④ 일자리 수요 근거
B15: 수요처 유형 · 규모 · 증감 추세 | C15: - 수요처 : 1) 극초기(Seed ~ Pre-A) 기술·서비스 스타트업 2) 창업진흥원, 지자체 테크노파크 등 정부, 지자체, 공공기관 3) 오픈 이노베이션 추진 기업 4) 대학 산학협력단, 기술지주회사, 정부출연연구기관 - 시장 규모 : AC등록사 규모는 530개사(2025년), 투자 규모는 3조8천억원, 누적 투자 건수는 11,000여건. - 증감 추세 : 1) 양적, 질적으로 성장 및 고도화 추세 : 정부의 기술창업 육성정책 및 공공 연계 강화, 오픈 이노베이션 시장의 급성장, 벤처스튜디오 모델(공동 창업자 모델) 확산 2) 시장의 양극화 및 선별성 강화(투자 쏠림 및 양극화 심화(AI, 로보틱스, 바이오/헬스캐어), 보육(Mentoring) 능력 중심 AC로 재편
B16: 뒷받침 근거 | C16: 복합 | E16: - 정부의 기술 및 창업 투자 정책 + AC생태계 변화
B17: ⑤ 진입 방법
B18: 필요 자격 · 교육 | C18: - 필요 자격 : 1) 기업/기관 3년 이상 경력자 + 양성과정 이수 (가장 현실적인 경로) 2) 변호사, 공인회계사, 변리사, 기술사, 경영지도사/기술지도사 (3년 이상)전문 자격증 및 학위 보유자 3) 창업 및 투자 경험자 - 교육 : 1) 초기투자액셀러레이터협회(KAIA) 전문인력 양성과정 (필수 추천) 2) 한국벤처캐피탈협회(KVCA) 벤처투자 실무 과정 3) 공공 지원기관 시니어 멘토·창업보육 과정 (서울시50플러스재단 및 지자체 신중년지원센터, 창업진흥원 평가위원 등록)
B19: 초기 준비물 · 비용 | C19: - 전문인력 양성과정 교육비 및 네트워킹 행사 참석 비용 150~280만원.
B20: 일감 얻는 경로 (플랫폼·기관 실명) | C20: - 공공·지자체 창업 평가위원 및 멘토 풀(Pool) 등록 (가장 빠른 진입) : K-Startup 창업포털, K-ICT 창업멘토링센터, 지역 창조경제혁신센터 및 테크노파크(TP) - AC·VC 법인의 파트너/외부 전문 심사역 활동 : 상근/비상근 전문인력 등록, 액셀러레이팅 프로그램의 담당 멘토 및 데모데이 심사위원 참여 - 대학 산학협력단 및 창업보육센터(BI) 전담 멘토, 프리랜서 창업 컨설팅 및 재능마켓 수주 등
B21: ⑥ N잡 적합성 검증
B22: 10조건 | C22: ①시간 유연성 | D22: ②체력 감당 | E22: ③직업 이미지 | F22: ④재미 | G22: ⑤전문성 축적 | H22: ⑥일한 만큼 이상 수익 | I22: ⑦우상향 수익 | J22: ⑧충분한 수요 | K22: ⑨진입 가능성 | L22: ⑩직업적 자부심
B23: 판정 ○ △ ✕ | C23: △ | D23: ○ | E23: ○ | F23: ○ | G23: ○ | H23: ○ | I23: ○ | J23: ○ | K23: ○ | L23: ○
B24: 판정 근거 (△·✕ 위주로) | C24: ① △ — 전업으로 근무하는 경우가 많음. 비상근이나 파트너급 이상 자리는 시간적 유연성 있음
B25: 종합 판정 | C25: 적합 | E25: 10조건 중 9개 통과, 1개 조건부
B26: ⑦ 실제 종사자 (1명)
B27: 이름 · 소속 · 경력 | C27: - 이한선 전문위원 / MYSC 2.5년 바이오, 헬스캐어 / 제약회사 영업/마케팅 15년, 청년창업사관학교 8년, 서울50+ 입주사 20개사 및 경기도 사회적기업 10개사 담당, 경영지도사 자격증 보유. 60대 초반. - 임성준 파트너 / MYSC 파트너 & 파스타벤처스 대표 / 네이버,카카오 등 12년 이상 근무. 스테이즈 스타트업 창업/운영 10년. MYSC 이사 3년 근무, MYSC 파트너(26.3~ ). 한성대 특임교수, 작가 (AI x 스타트업 등 저서 6권, 브런치 작가). 공인중개사 자격증 보유.
B28: 확인 출처 (기사·인터뷰·블로그·유튜브·플랫폼 프로필 등) | C28: - 스타트업 엑셀러레이터(URL ①), MYSC 웹사이트(URL ②), 이한선 위원(URL ③), 임성준 대표(URL ④)
B29: 컨택 포인트 (연락처·이메일·SNS·소속 기관) | C29: - 이한선 위원 : M : 010-6211-2036 / E : hslee@mysc.co.kr
B30: 인터뷰 가능성 | C30: 상 | E30: - 청년창업사관학교 교수 경력 8년 보유.
B31: ⑧ 참고 URL (오른쪽 끝 칸 = 확인일)
B32: URL ① | C32: https://search.naver.com/search.naver?where=nexearch&sm=top_hty&fbm=0&ie=utf8&query=%EC%8A%A4%ED%83%80%ED%8A%B8%EC%97%85+%EC%97%91%EC%85%80%EB%9F%AC%EB%A0%88%EC%9D%B4%ED%84%B0&ackey=6c5u303v
B33: URL ② | C33: https://www.mysc.co.kr/
B34: URL ③ | C34: https://blog.naver.com/blogmysc/224223520992
B35: URL ④ | C35: https://search.naver.com/search.naver?where=nexearch&sm=tab_etc&mra=bjky&pkid=1&os=17491014&qvt=0&query=%EC%9E%84%EC%84%B1%EC%A4%80
B36: URL ⑤
B38: ※ 연노랑 칸에 입력합니다. L열은 확인일입니다.

Sheet 013_AI소상공인 컨설턴트
B2: Job No. 013 AI소상공인 컨설턴트
B3: 2. 경영·창업 자문형 | 워크위즈 N잡스쿨 · 잡별 시장조사 시트
B5: ① 기본 정보
B6: 직업명 · 별칭 | C6: AI소상공인 컨설턴트
B7: 한 줄 소개 (30자 내외) | C7: 소상공인이 AI 도구로 홍보·주문·고객관리를 자동화하도록 돕는 일
B8: 수집 상태 · 담당자 | C8: 완료 | E8: 담당 : 정재웅
B9: ② 핵심 지표 6종
B10: 지표 | C10: 초기비용 | D10: 월수익(만원) | E10: 성장성 | F10: 진입난이도 | G10: 주간 소요시간 | H10: 체력부담 | I10: 지표 근거 · 비고
B11: 값 | C11: ₩ 50만 미만 | D11: 100~300 | E11: ↗↗ 높음 | F11: ★★★★ | G11: 주 5~15시간 | H11: 하 | I11: AI도구 구축 월수익은 거래처 2~3곳 기준 100~300만원. 리테이너 기준 월수익은 거래처당 40~90만원
B12: ③ 하는 일
B13: 하는 일 (3줄 요약) | C13: - AI기반 마케팅 지원: 생성형 AI(ChatGPT, Gemini 등)를 활용한 홍보 문구 작성, SNS 카드뉴스/영상 제작, 블로그 마케팅 자동화 지원 - 매장 운영 자동화: AI 예약 시스템, 스마트 오더, 테이블 오더 및 무인 결제 시스템 구축 자문 - 상권 분석 및 매출 예측: 빅데이터 분석 도구를 활용한 지역 상권 및 유동인구 분석, 적정 메뉴/상품 가격 책정 - 고객 응대 자동화: AI 챗봇 구축을 통한 24시간 문의 대응 및 고객 관리(CRM) 시스템 도입
B14: ④ 일자리 수요 근거
B15: 수요처 유형 · 규모 · 증감 추세 | C15: - 수요처는 개인사업에 AI를 이용한 마케팅 업무를 도입하고 디지털 전환하려는 730만 소상공인들이다. - 중소벤처기업부는 소상공인 지원 예산을 역대 최대 규모(5조원 이상)로 편성하였으며, 이 중 '소상공인 AI 활용지원 사업' 등을 신규 신설해 직접 예산 지원중임 - 수요는 급증세. 정부가 단순 자금·바우처 지원에서 'AI·디지털 전환(AX)' 중심으로 정책적 지원 패러다임이 전환되었고 소상공인들도 AI 도입 의향은 높으나 기술적 한계로 현장에서 직접 지도해줄 컨설턴트의 니즈가 폭증하는 추세
B16: 뒷받침 근거 | C16: 복합 | E16: 정부지원사업 연계 : 소상공인시장진흥공단 등의 스마트상점 보급사업 및 디지털 전환 지원금
B17: ⑤ 진입 방법
B18: 필요 자격 · 교육 | C18: 필수 자격 없음. 정부(소상공인시장진흥공단)나 지자체(경제진흥원/신용보증재단), 민간금융기관(하나파워온)과 연계된 AX교육 2~3개월 이면 진입 가능
B19: 초기 준비물 · 비용 | C19: 노트북, 광고 계정, 포트폴리오용 샘플 리포트. 실비 50만원 미만
B20: 일감 얻는 경로 (플랫폼·기관 실명) | C20: 크몽·숨고 전문가 등록, 소상공인시장진흥공단 컨설턴트 풀, 지자체 소상공인 지원센터, 기존 거래처 소개
B21: ⑥ N잡 적합성 검증
B22: 10조건 | C22: ①시간 유연성 | D22: ②체력 감당 | E22: ③직업 이미지 | F22: ④재미 | G22: ⑤전문성 축적 | H22: ⑥일한 만큼 이상 수익 | I22: ⑦우상향 수익 | J22: ⑧충분한 수요 | K22: ⑨진입 가능성 | L22: ⑩직업적 자부심
B23: 판정 ○ △ ✕ | C23: ○ | D23: ○ | E23: ○ | F23: △ | G23: ○ | H23: ○ | I23: ○ | J23: △ | K23: ○ | L23: ○
B24: 판정 근거 (△·✕ 위주로) | C24: ④ △ — 내향적인 성향이거나 IT기업 은퇴후 얼마 안됬으면 적응 기간 필요. 정부나 지자체 기관 소속이거나 일정기간 프로젝트 진행하다가 프리랜서가 되면 발로 뛰는 영업이 필요. AI도구/시스템 구축후 현장 직원들이 지속 사용 어려해해서 기존 방식으로 원위치하는 경향 있음. ⑧ △ — 소상공인 특성상 직접 매출로 연결되는 성과가 보이거나 가시적인 시스템 구축이 필요해야 비용 지출하려는 경향이 있음
B25: 종합 판정 | C25: 적합 | E25: 10조건 중 8개 통과, 2개 조건부
B26: ⑦ 실제 종사자 (1명)
B27: 이름 · 소속 · 경력 | C27: - 이종문 컨설턴트 / 프리랜서 / 디지털 마케팅 컨설팅 20년, 現 은평구 소속 AI소상공인 컨설팅 2년차
B28: 확인 출처 (기사·인터뷰·블로그·유튜브·플랫폼 프로필 등) | C28: AI소상공인컨설턴트 관련 기사 (URL ①, ②)
B29: 컨택 포인트 (연락처·이메일·SNS·소속 기관) | C29: 010-9455-8916 / Email : zzongaa@gmail.com
B30: 인터뷰 가능성 | C30: 상 | E30: - 디지털 마케팅 및 AI소상공인 컨설팅 영역 강사 경험 다수
B31: ⑧ 참고 URL (오른쪽 끝 칸 = 확인일)
B32: URL ① | C32: https://blog.naver.com/sbmabiz/224346781609
B33: URL ② | C33: https://blog.naver.com/mbb_choi/224362182087
B34: URL ③
B35: URL ④
B36: URL ⑤
B38: ※ 연노랑 칸에 입력합니다. L열은 확인일입니다.

Sheet 014_AI중소기업 컨설턴트
B2: Job No. 014 AI중소기업 컨설턴트
B3: 2. 경영·창업 자문형 | 워크위즈 N잡스쿨 · 잡별 시장조사 시트
B5: ① 기본 정보
B6: 직업명 · 별칭 | C6: AI중소기업 컨설턴트
B7: 한 줄 소개 (30자 내외) | C7: 중소기업의(사회적 기업 포함) 업무 전반에 AI를 도입해 생산성을 높이도록 자문하는 일
B8: 수집 상태 · 담당자 | C8: 완료 | E8: 담당 : 정재웅
B9: ② 핵심 지표 6종
B10: 지표 | C10: 초기비용 | D10: 월수익(만원) | E10: 성장성 | F10: 진입난이도 | G10: 주간 소요시간 | H10: 체력부담 | I10: 지표 근거 · 비고
B11: 값 | C11: ₩ 50만 미만 | D11: 80~300 | E11: ↗ 보통 | F11: ★★★★★ | G11: 주 5~15시간 | H11: 하 | I11: - 겸업 컨설턴트 : 150~300만원/월 (테크노파크 평가위원) - 전업 컨설턴트 : 300~700만원/월(프리랜서), 500~800만원/월(컨설팅펌/상주 전문위원)
B12: ③ 하는 일
B13: 하는 일 (3줄 요약) | C13: - 기업 전체의 업무 프로세스 혁신, 스마트공장 고도화, 제품/서비스 R&D, 그리고 조직 내 AI 역량 내재화 등 거시적이고 구조적인 영역을 담당 - 비즈니스 진단 및 AI 도입 타당성 평가: 현재 인프라, 재무 상태, 업종 특성을 분석하여 AI를 도입시 가장 큰 효과를 낼 수 있는 부서나 공정을 발굴 - 업무 프로세스 자동화 및 솔루션 연계의 경우 스마트공장 데이터와 AI를 결합한 예방 보전(설비 고장 예측)이나 불량률 감소 시스템 구축 지원. - 정부 지원사업 연계된 '중소기업 스마트서비스 지원사업'이나 'AI 맞춤 컨설팅 및 훈련 프로그램' 등의 정부 과제 기획서 작성하고 수행 과정 총괄.
B14: ④ 일자리 수요 근거
B15: 수요처 유형 · 규모 · 증감 추세 | C15: - 국내 수십만 개에 달하는 중소기업 중, 디지털 전환(DX) 단계 넘어 AI를 결합하는 AX단계로 진입해야 하는 기업 전체가 핵심 수요처 - 정부는 제조 AI 전환(M.AX) 예산(4,000억 원대 이상) 및 중기부의 스마트서비스/스마트공장 보급사업에 매년 대규모 예산을 집행 - 수요는 급증세 : 중소기업의 구인난과 인건비 압박 극복 필요. 정부 지원 사업의 패러다임 변화(데이터를 활용한 AI 예측 및 AX 고도화), 중소기업 기술 장벽과 내부 역량 부족
B16: 뒷받침 근거 | C16: 복합 | E16: 정부지원사업 : 중소벤처기업진흥공단의 제조AI 전환 예산 및 중소벤처기업부의 스마트 서비스/스마트 공장 보급사업
B17: ⑤ 진입 방법
B18: 필요 자격 · 교육 | C18: - 민간 전문 자격 : 1) AI산업컨설턴트, 디지털전환(DX) 컨설턴트 (Expert / 1급 / 2급) - 한국인공지능협회, 한국스마트컨설팅협회 2) 최근에는 AX(AI Transformation) 컨설턴트, AI데이터 분석사 자격증 필요 - 국가 전문자격/기술 자격(우대 요건) : 1) 경영지도사 / 기술지도사 (국가전문자격), 2) AICE (AI Certificate for Everyone) - KT 등에서 주관.
B19: 초기 준비물 · 비용 | C19: 최신 노트북(100~250만원), 광고 계정, 포트폴리오용 샘플 리포트. 실비 100만원 미만
B20: 일감 얻는 경로 (플랫폼·기관 실명) | C20: - 정부, 공공기관 연계 : 중소벤처기업부, 소상공인시장진흥공단, 테크노파크, 경제진흥원, 신용보증재단, 창원진흥원, 경제과학진흥원 컨설턴트 풀 - 민간 기업 및 컨설팅 펌 : 테크 솔루션 협력사 (캐시노트, 로보아자, 주요 AI SaaS 스타트업 등), HRD 및 교육 전문 기업(휴넷, 에이블런 등), 컨설팅펌[한국능률협회컨설팅(KMAC)이나 전문 DX 컨설팅사] 컨설턴트나 전문위원으로 등록
B21: ⑥ N잡 적합성 검증
B22: 10조건 | C22: ①시간 유연성 | D22: ②체력 감당 | E22: ③직업 이미지 | F22: ④재미 | G22: ⑤전문성 축적 | H22: ⑥일한 만큼 이상 수익 | I22: ⑦우상향 수익 | J22: ⑧충분한 수요 | K22: ⑨진입 가능성 | L22: ⑩직업적 자부심
B23: 판정 ○ △ ✕ | C23: ○ | D23: ○ | E23: ○ | F23: ○ | G23: ○ | H23: ○ | I23: △ | J23: ○ | K23: △ | L23: ○
B24: 판정 근거 (△·✕ 위주로) | C24: ⑥ △ — 기업 소속 AI 전문가로서는 파트타임 수준의 수입 ⑨ △ — 국가 전문 자격증이나 민간 전문 자격증 보유 필수
B25: 종합 판정 | C25: 적합 | E25: 10조건 중 8개 통과, 2개 조건부
B26: ⑦ 실제 종사자 (1명)
B27: 이름 · 소속 · 경력 | C27: - 이재우 컨설턴트 / 상상우리 / 전 IT분야 30년 컨설팅 경력, 현 AI중소기업(사회적기업) 컨설턴트 1년차
B28: 확인 출처 (기사·인터뷰·블로그·유튜브·플랫폼 프로필 등) | C28: - AI중소기업 컨설턴트란?(URL①), AI 도입 Tool 및 지원 사업(URL②)
B29: 컨택 포인트 (연락처·이메일·SNS·소속 기관) | C29: Email : jwl1722@naver.com
B30: 인터뷰 가능성 | C30: 상 | E30: - 현재 상상우리에서 AI중소기업 컨설팅 분야에서 강의 가능
B31: ⑧ 참고 URL (오른쪽 끝 칸 = 확인일)
B32: URL ① | C32: https://search.naver.com/search.naver?sm=tab_hty.top&where=nexearch&ssc=tab.nx.all&query=AI%EC%A4%91%EC%86%8C%EA%B8%B0%EC%97%85+%EC%BB%A8%EC%84%A4%ED%84%B4%ED%8A%B8%EB%9E%80&oquery=AI%EC%A4%91%EC%86%8C%EA%B8%B0%EC%97%85+%EC%BB%A8%EC%84%A4%ED%84%B4%ED%8A%B8&tqi=jpRU0lqX6IgMibjjqvw-297928&ackey=lq3v0d4d
B33: URL ② | C33: https://www.techmarket.kr/ai/aiInfoDetail.do?idx=19124
B34: URL ③
B35: URL ④
B36: URL ⑤
B38: ※ 연노랑 칸에 입력합니다. L열은 확인일입니다.

Sheet 015_면접심사위원
B2: Job No. 015 면접심사위원
B3: 2. 경영·창업 자문형 | 워크위즈 N잡스쿨 · 잡별 시장조사 시트
B5: ① 기본 정보
B6: 직업명 · 별칭 | C6: 면접심사위원
B7: 한 줄 소개 (30자 내외) | C7: 기업·공공기관 채용 면접에 외부 위원으로 참여해 지원자를 평가하는 일
B8: 수집 상태 · 담당자 | C8: 완료 | E8: - 담당 : 정재웅
B9: ② 핵심 지표 6종
B10: 지표 | C10: 초기비용 | D10: 월수익(만원) | E10: 성장성 | F10: 진입난이도 | G10: 주간 소요시간 | H10: 체력부담 | I10: 지표 근거 · 비고
B11: 값 | C11: ₩ 50만 미만 | D11: 40 ~ 120 | E11: ↗ 보통 | F11: ★★★ | G11: 주 5시간 미만 | H11: 하 | I11: - 부업(월 2~4회 활동) : 월 40 ~ 120만원 수준 - 활발한 활동 및 전업 프리랜서형 : 월 150 ~ 300만원 (여러 기관의 평가위원 풀에 등록되어 주 1~2회 이상 활동)
B12: ③ 하는 일
B13: 하는 일 (3줄 요약) | C13: - 공정성과 객관성 유지 : 주관적인 편견이나 선입견을 배제하고, 사전에 마련된 평가 기준표에 따라 모든 지원자를 공정하게 심사. - 조직 적합성 검증 : 지원자의 직무 역량뿐만 아니라 조직의 문화, 가치관(비전), 팀워크에 잘 어우러질 수 있는 인재인지를 판별. - 기업(기관)의 얼굴 : 면접관은 지원자에게 조직의 첫인상을 전달하는 대표자이기도 하므로, 정중하고 전문적인 태도로 면접 분위기 조성
B14: ④ 일자리 수요 근거
B15: 수요처 유형 · 규모 · 증감 추세 | C15: - 수요처 : 1) 공공기관 및 공기업 : NCS(국가직무능력표준) 및 블라인드 채용 의무화로 인해 공정성과 전문성을 갖춘 외부 면접위원들 필요. 2) 대기업 및 중견·중소기업 : 채용의 전문성을 높이고 사내 면접관의 편향을 줄이기 위해 전문 면접관을 아웃소싱 또는 대행기관 활용. 3) 지자체 및 공공 일자리 사업단 : 청년취업 지원 프로그램, 신중년 경력형 일자리, 지역인재 및 경력직, 공무원 채용시 심사위원 초빙. 4) 대학 및 고등학교 (입시, 대입): 학생부종합전형 등 수시 면접 평가와 편입학, 로스쿨, 특수대학원 면접 위해 전문가 심사위원 대거 수요. - 규모 및 증감 추세 : 1) 전통적 대면 면접 뿐만 아니라, 글로벌 면접 서비스 및 디지털 평가 솔루션시장 또한 연평균 두 자리 수 이상 가파른 성장세. 2) AI 평가의 한계를 보완하기 위해 전문 인력이 직접 심층 역량을 평가하는 휴먼 면접관의 가치는 더욱 공고해지는 추세.
B16: 뒷받침 근거 | C16: 복합 | E16: - 투명성을 높이기 위한 법적·제도적 장치가 강화됨. 검증된 외부 면접위원을 파견·매칭하는 HR 컨설팅 및 채용 대행 시장이 확대되는 추세
B17: ⑤ 진입 방법
B18: 필요 자격 · 교육 | C18: - 경력 요건 (가장 중요) : 대기업·중견기업 인사(HR) 부서 팀장·임원급, 공공기관 채용 담당관, 또는 산업 분야에서 10~15년 이상 경력의 전문가. - 연령 및 소속 : 공공기관이나 지자체 산하 일자리 사업(시니어 전문위원 등)의 경우 일정 연령(장노년층 경력 활용) 요구. - 교육 : 공신력 있는 기관(한국바른채용인증원, 한국능률협회, 한국전문면접관협회 등)에서 주관하는 채용전문면접관(또는 면접위원) 양성 과정 (8~16시간)을 이수하고 자격을 취득.
B19: 초기 준비물 · 비용 | C19: - 면접관 양성 과정 교육비/자격증비 50 ~ 80만원 (한국바른채용인증원, 한국능률협회 등)
B20: 일감 얻는 경로 (플랫폼·기관 실명) | C20: 1. 전문 매칭 플랫폼 및 양성 기관 : 1) 민간 전문기관 및 플랫폼 : 한국앙코르커리어('위원해' 플랫폼)나 한국바른채용인증원 등 전문 교육 및 인재 매칭 기관에 이력과 자격 정보를 등록. 2) HR 컨설팅 및 채용 대행사 풀 : 공공기관이나 대기업의 채용을 위탁받아 수행하는 전문 HR 에이전시의 면접위원 데이터베이스에 등록. 2. 공공기관 및 지자체 공개 모집·추천 : 1) 나라일터 및 공공기관 홈페이지 : 행정안전부의 '나라일터'나 각 중앙부처, 지자체, 공공기관의 홈페이지 공고란에 '외부 면접위원(평가위원) 풀 공개 모집' 2) 지자체 산하 기관 및 일자리센터 : 시·군·구청이나 일자리 재단 등에서 진행하는 중장년 경력 활용사업, 청년 면접 지원 사업 등의 심사위원으로 위촉. 3. 인적 네트워크 및 학회·협회 : 1) 전문가 커뮤니티 및 동문 네트워크 : 심사위원으로 활발히 활동하고 있는 선배 위원이나 관련 협회 회원들과의 교류 통해 구인 공고가 외부에 뜨기전 추천을 받아 참여. 2) 출신 분야 인맥 : 본인이 오랫동안 종사했던 전직 직장(대기업, 공공기관, 금융권 등)의 네트워크나 관련 업계, 협회를 통해 자문 및 심사 요청 접수.
B21: ⑥ N잡 적합성 검증
B22: 10조건 | C22: ①시간 유연성 | D22: ②체력 감당 | E22: ③직업 이미지 | F22: ④재미 | G22: ⑤전문성 축적 | H22: ⑥일한 만큼 이상 수익 | I22: ⑦우상향 수익 | J22: ⑧충분한 수요 | K22: ⑨진입 가능성 | L22: ⑩직업적 자부심
B23: 판정 ○ △ ✕ | C23: ○ | D23: ○ | E23: ○ | F23: ○ | G23: ○ | H23: △ | I23: △ | J23: ○ | K23: ○ | L23: ○
B24: 판정 근거 (△·✕ 위주로) | C24: ⑥ △ — 일한 만큼의 수입 ⑦ △ — 등록된 단체 및 협회, 마케팅 능력에 따라 면접심사위원들의 수입 차이가 발생.
B25: 종합 판정 | C25: 적합 | E25: 10조건 중 8개 통과, 2개 조건부
B26: ⑦ 실제 종사자 (1명)
B27: 이름 · 소속 · 경력 | C27: - 심영재 면접심사위원(4년) / 한국소비자협회 상무(10년) / 창업멘토(4년), 면접심사위원 강사(2년) / 전 미래에셋증권 지점장(15년) 경력.
B28: 확인 출처 (기사·인터뷰·블로그·유튜브·플랫폼 프로필 등) | C28: - 면접심사위원 이란(URL ①), 면접심사위원 모집 공고(URL ②, URL ③)
B29: 컨택 포인트 (연락처·이메일·SNS·소속 기관) | C29: - T : 010-8417-7123 / E : isobi777@naver.com
B30: 인터뷰 가능성 | C30: 상 | E30: - 면접심사위원 양성과정에서 강사로 활동중.
B31: ⑧ 참고 URL (오른쪽 끝 칸 = 확인일)
B32: URL ① | C32: https://search.naver.com/search.naver?sm=tab_hty.top&where=nexearch&ssc=tab.nx.all&query=%EB%A9%B4%EC%A0%91%EC%8B%AC%EC%82%AC%EC%9C%84%EC%9B%90&oquery=%EC%8B%AC%EC%98%81%EC%9E%AC+%ED%95%9C%EA%B5%AD%EC%86%8C%EB%B9%84%EC%9E%90%ED%98%91%ED%9A%8C&tqi=jq0cRlqX5mhssAv1diZ-096540&ackey=0aol2sfc
B33: URL ② | C33: https://www.goean.kr/goean/na/ntt/selectNttInfo.do?mi=4447&nttSn=1100221
B34: URL ③ | C34: https://www.goedy.kr/goedy/na/ntt/selectNttInfo.do?mi=10224&nttSn=1678594
B35: URL ④
B36: URL ⑤
B38: ※ 연노랑 칸에 입력합니다. L열은 확인일입니다.

Sheet 016_평판조회 전문가
B2: Job No. 016 평판조회 전문가
B3: 2. 경영·창업 자문형 | 워크위즈 N잡스쿨 · 잡별 시장조사 시트
B5: ① 기본 정보
B6: 직업명 · 별칭 | C6: 평판조회 전문가
B7: 한 줄 소개 (30자 내외) | C7: 채용 예정자의 전 직장 평판을 확인해 검증 보고서를 작성하는 일
B8: 수집 상태 · 담당자 | C8: 수집중 | E8: 담당 : 정재웅
B9: ② 핵심 지표 6종
B10: 지표 | C10: 초기비용 | D10: 월수익(만원) | E10: 성장성 | F10: 진입난이도 | G10: 주간 소요시간 | H10: 체력부담 | I10: 지표 근거 · 비고
B11: 값 | C11: ₩ 50만 미만 | D11: 150~350+ | E11: ↗ 보통 | F11: ★★★ | G11: 주 5시간 미만 | H11: 하 | I11: - 프리랜서(초기·중급) : 월 150 ~ 350만원 - 전문 컨설턴트(고경력): 월 500 ~ 1,000만원+ - 전문기업/서치펌(상근): 월 330 ~ 580만원
B12: ③ 하는 일
